Workbook

Sheet Original Data
A1: ID_Proyek | B1: Jenis_Proyek | C1: Lokasi | D1: Nama_Proyek | E1: Panjang_Jalan | F1: Tanggal_Mulai | G1: Tanggal_Selesai | H1: Durasi_Proyek | I1: Anggaran | J1: Kontraktor | K1: Sumber_Dana
A2: CN-0001-2023 | B2: Jalan Raya | C2: Tomohon | D2: Pembangunan Jalan Raya Tomohon | E2: 31.76 | F2: 45064 | G2: 45199 | H2: 135 | I2: 4887210098 | J2: Perum Lailasari Hariyah (Persero) Tbk | K2: APBN 2023
A3: CN-0002-2023 | B3: Gedung | C3: Makassar | D3: Pembangunan Gedung Pemerintah Makassar | F3: 45118 | G3: 45288 | H3: 170 | I3: 2534374084 | J3: PT A | K3: APBD 2023
A4: CN-0003-2023 | B4: Jalan Raya | C4: Depok | D4: Pembangunan Jalan Raya Depok | E4: 46.32 | F4: 45017 | G4: 45162 | H4: 145 | I4: 718301152 | J4: Perum Yuniar Hakim Tbk | K4: APBD 2023
A5: CN-0004-2023 | B5: Jalan Raya | C5: Makassar | D5: Pembangunan Jalan Raya Makassar | E5: 20.81 | F5: 45263 | G5: 45413 | H5: 150 | I5: 1402997498 | J5: PT A | K5: APBN 2023
A6: CN-0005-2023 | B6: Jembatan | C6: Bau-Bau | D6: Rehabilitasi Jembatan Bau-Bau | F6: 45063 | G6: 45233 | H6: 170 | I6: 973230661 | J6: PT C | K6: APBD 2023
A7: CN-0006-2023 | B7: Drainase | C7: Bandung | D7: Perbaikan Drainase Bandung | E7: 1.34 | F7: 44927 | G7: 44994 | H7: 67 | I7: 567100601 | J7: Perum Lailasari Hariyah (Persero) Tbk | K7: APBD 2023
A8: CN-0007-2023 | B8: Jembatan | C8: Jakarta | D8: Rehabilitasi Jembatan Jakarta | F8: 45035 | G8: 45339 | H8: 304 | I8: 4695148263 | K8: APBD 2023
A9: CN-0008-2023 | B9: Jembatan | C9: Medan | D9: Rehabilitasi Jembatan Medan | F9: 44989 | G9: 45301 | H9: 312 | I9: 1359388722 | J9: CV Sihombing | K9: APBD 2023
A10: CN-0009-2023 | B10: Jalan Raya | C10: Bandung | D10: Pembangunan Jalan Raya Bandung | E10: 37.14 | F10: 44948 | G10: 45054 | H10: 106 | I10: 4866835678 | J10: Perum Yuniar Hakim Tbk | K10: APBD 2023
A11: CN-0010-2023 | B11: Drainase | C11: Surabaya | D11: Perbaikan Drainase Surabaya | E11: 1.17 | F11: 45036 | G11: 45119 | H11: 83 | I11: 2094613916 | J11: PT D | K11: APBN 2023
A12: CN-0011-2023 | B12: Jalan Raya | C12: Depok | D12: Pembangunan Jalan Raya Depok | E12: 24.95 | F12: 45226 | G12: 45403 | H12: 177 | I12: 4695488551 | J12: PT A | K12: APBD 2023
A13: CN-0012-2023 | B13: Gedung | C13: Jakarta | D13: Pembangunan Gedung Pemerintah Jakarta | F13: 45320 | G13: 45161 | H13: -159 | I13: 1108345388 | J13: CV Sihombing | K13: APBN 2023
A14: CN-0013-2023 | B14: Drainase | C14: Bandung | D14: Perbaikan Drainase Bandung | E14: 3.51 | F14: 45338 | G14: 45128 | H14: -210 | I14: 4343883992 | J14: PT A | K14: APBN 2023
A15: CN-0014-2023 | B15: Jembatan | C15: Tomohon | D15: Rehabilitasi Jembatan Tomohon | F15: 45249 | G15: 45590 | H15: 341 | I15: 3933046847 | J15: PT A | K15: APBD 2023
A16: CN-0015-2023 | B16: Jembatan | C16: Makassar | D16: Rehabilitasi Jembatan Makassar | F16: 45179 | G16: 45400 | H16: 221 | I16: 3381767421 | J16: CV Sihombing | K16: APBD 2023
A17: CN-0016-2023 | B17: Flyover | C17: Bandung | D17: Pembangunan Flyover Bandung | F17: 45128 | G17: 45204 | H17: 76 | I17: 4180846335 | J17: PT C | K17: APBN 2023
A18: CN-0017-2023 | B18: Jalan Raya | C18: Medan | D18: Pembangunan Jalan Raya Medan | E18: 35.31 | F18: 44938 | G18: 44985 | H18: 47 | I18: 2760864114 | K18: APBN 2023
A19: CN-0018-2023 | B19: Jalan Raya | C19: Depok | D19: Pembangunan Jalan Raya Depok | E19: 13.12 | F19: 44969 | G19: 45123 | H19: 154 | I19: 2176989260 | J19: PT C | K19: APBN 2023
A20: CN-0019-2023 | B20: Flyover | C20: Surabaya | D20: Pembangunan Flyover Surabaya | F20: 44967 | G20: 45260 | H20: 293 | I20: 4508289840 | J20: PT B | K20: APBD 2023
A21: CN-0020-2023 | B21: Drainase | C21: Medan | D21: Perbaikan Drainase Medan | E21: 3.69 | F21: 44936 | G21: 45295 | H21: 359 | I21: 811513657 | J21: PT A | K21: APBN 2023
A22: CN-0021-2023 | B22: Gedung | C22: Bandung | D22: Pembangunan Gedung Pemerintah Bandung | F22: 45129 | G22: 45264 | H22: 135 | I22: 832981859 | J22: CV Sihombing | K22: APBD 2023
A23: CN-0022-2023 | B23: Gedung | C23: Jakarta | D23: Pembangunan Gedung Pemerintah Jakarta | F23: 45074 | G23: 45326 | H23: 252 | I23: 3757105268 | K23: APBN 2023
A24: CN-0023-2023 | B24: Gedung | C24: Bau-Bau | D24: Pembangunan Gedung Pemerintah Bau-Bau | F24: 45128 | G24: 45275 | H24: 147 | I24: 4790525232 | J24: CV Sihombing | K24: APBN 2023
A25: CN-0024-2023 | B25: Drainase | C25: Medan | D25: Perbaikan Drainase Medan | E25: 1.7 | F25: 45041 | G25: 45102 | H25: 61 | I25: 1383396199 | J25: PT B | K25: APBN 2023
A26: CN-0025-2023 | B26: Jembatan | C26: Medan | D26: Rehabilitasi Jembatan Medan | F26: 44974 | G26: 45082 | H26: 108 | I26: 2462450365 | J26: Perum Yuniar Hakim Tbk | K26: APBN 2023
A27: CN-0026-2023 | B27: Drainase | C27: Tomohon | D27: Perbaikan Drainase Tomohon | E27: 1.83 | F27: 45271 | G27: 45311 | H27: 40 | I27: 1414817147 | J27: CV Sihombing | K27: APBN 2023
A28: CN-0027-2023 | B28: Flyover | C28: Depok | D28: Pembangunan Flyover Depok | F28: 45160 | G28: 45415 | H28: 255 | I28: 4665481372 | K28: APBD 2023
A29: CN-0028-2023 | B29: Jembatan | C29: Jakarta | D29: Rehabilitasi Jembatan Jakarta | F29: 44945 | G29: 45037 | H29: 92 | I29: 3016693972 | J29: Perum Yuniar Hakim Tbk | K29: APBN 2023
A30: CN-0029-2023 | B30: Jalan Raya | C30: Bau-Bau | D30: Pembangunan Jalan Raya Bau-Bau | E30: 40.5 | F30: 45033 | G30: 45370 | H30: 337 | I30: 2187758490 | J30: CV Sihombing | K30: APBD 2023
A31: CN-0030-2023 | B31: Jembatan | C31: Depok | D31: Rehabilitasi Jembatan Depok | F31: 45241 | G31: 45505 | H31: 264 | I31: 1240232201 | J31: Perum Yuniar Hakim Tbk | K31: APBN 2023
A32: CN-0031-2023 | B32: Flyover | C32: Makassar | D32: Pembangunan Flyover Makassar | F32: 45118 | G32: 45256 | H32: 138 | I32: 4866732289 | J32: PT C | K32: APBD 2023
A33: CN-0032-2023 | B33: Jembatan | C33: Bau-Bau | D33: Rehabilitasi Jembatan Bau-Bau | F33: 44943 | G33: 45027 | H33: 84 | I33: 2228528699 | J33: CV Sihombing | K33: APBN 2023
A34: CN-0033-2023 | B34: Drainase | C34: Bandung | D34: Perbaikan Drainase Bandung | E34: 1.89 | F34: 45036 | G34: 45313 | H34: 277 | I34: 2685215729 | K34: APBN 2023
A35: CN-0034-2023 | B35: Drainase | C35: Bau-Bau | D35: Perbaikan Drainase Bau-Bau | E35: 1.49 | F35: 45076 | G35: 45355 | H35: 279 | I35: 1491624045 | J35: Perum Yuniar Hakim Tbk | K35: APBD 2023
A36: CN-0035-2023 | B36: Jembatan | C36: Bandung | D36: Rehabilitasi Jembatan Bandung | F36: 45240 | G36: 44995 | H36: -245 | I36: 2006686424 | J36: PT D | K36: APBN 2023
A37: CN-0036-2023 | B37: Gedung | C37: Depok | D37: Pembangunan Gedung Pemerintah Depok | F37: 45208 | G37: 45388 | H37: 180 | I37: 3436590647 | J37: PT A | K37: APBD 2023
A38: CN-0037-2023 | B38: Drainase | C38: Makassar | D38: Perbaikan Drainase Makassar | E38: 1.38 | F38: 45223 | G38: 45586 | H38: 363 | I38: 3888778874 | K38: APBN 2023
A39: CN-0038-2023 | B39: Gedung | C39: Bandung | D39: Pembangunan Gedung Pemerintah Bandung | F39: 45072 | G39: 45108 | H39: 36 | I39: 1394109768 | J39: PT B | K39: APBD 2023
A40: CN-0039-2023 | B40: Drainase | C40: Medan | D40: Perbaikan Drainase Medan | E40: 0.23 | F40: 44932 | G40: 45108 | H40: 176 | I40: 1785906562 | J40: CV Sihombing | K40: APBN 2023
...

Sheet Raw Dataset
A1: ID_Proyek | B1: Jenis_Proyek | C1: Lokasi | D1: Nama_Proyek | E1: Tanggal_Mulai | F1: Tanggal_Selesai | G1: Anggaran | H1: Kontraktor
A2: CN-0001-2023 | B2: Drainase | C2: Bandung | D2: Perbaikan Drainase Bandung | E2: 44927 | F2: 44994 | G2: 649208256 | H2: PT. Lailasari Hariyah (Persero) Tbk
A3: CN-0001-2024 | B3: Drainase | C3: Surabaya | D3: Perbaikan Drainase Surabaya | E3: 45319 | F3: 45323 | G3: 326999652 | H3: CV Sihombing
A4: CN-0002-2023 | B4: Flyover | C4: Depok | D4: Pembuatan Flyover Depok | E4: 44927 | F4: 45062 | G4: 3474309188 | H4: CV Sihombing
A5: CN-0002-2024 | B5: Gedung | C5: Jakarta | D5: Perbaikan Gedung Pemerintah Jakarta | E5: 45320 | F5: 45336 | G5: 8587951510 | H5: CV Sihombing
A6: CN-0003-2023 | B6: Jalan Raya | C6: Bandung | D6: Perbaikan Jalan Raya Bandung | E6: 44928 | F6: 45239 | G6: 191505827
A7: CN-0003-2024 | B7: Gedung | C7: Tomohon | D7: Perbaikan Gedung Pemerintah Tomohon | E7: 45323 | F7: 45343 | G7: 8016851785 | H7: PT. Yuniar Hakim Tbk
A8: CN-0004-2023 | B8: Flyover | C8: Tomohon | D8: Pembuatan Flyover Tomohon | E8: 44928 | F8: 45006 | G8: 3979021821 | H8: PT D
A9: CN-0004-2024 | B9: Gedung | C9: Jakarta | D9: Perbaikan Gedung Pemerintah Jakarta | E9: 45325 | F9: 45342 | G9: 2153093275 | H9: PT. Yuniar Hakim Tbk
A10: CN-0005-2023 | B10: Drainase | C10: Jakarta | D10: Perbaikan Drainase Jakarta | E10: 44928 | F10: 45271 | G10: 683556997 | H10: PT A
A11: CN-0005-2024 | B11: Jembatan | C11: Bau-Bau | D11: Perbaikan Jembatan Bau-Bau | E11: 45327 | F11: 45353 | G11: 4636324090 | H11: PT. Lailasari Hariyah (Persero) Tbk
A12: CN-0006-2023 | B12: Drainase | C12: Tomohon | D12: Perbaikan Drainase Tomohon | E12: 44929 | F12: 45230 | G12: 663835414 | H12: PT B
A13: CN-0006-2024 | B13: Drainase | C13: Bandung | D13: Perbaikan Drainase Bandung | E13: 45329 | F13: 45360 | G13: 698540517 | H13: PT A
A14: CN-0007-2023 | B14: Flyover | C14: Medan | D14: Pembuatan Flyover Medan | E14: 44929 | F14: 45261 | G14: 2423693734 | H14: PT D
A15: CN-0007-2024 | B15: Drainase | C15: Depok | D15: Perbaikan Drainase Depok | E15: 45330 | F15: 45337 | G15: 313131839 | H15: PT D
A16: CN-0008-2023 | B16: Jalan Raya | C16: Bandung | D16: Perbaikan Jalan Raya Bandung | E16: 44929 | F16: 45041 | G16: 281077623 | H16: PT. Yuniar Hakim Tbk
A17: CN-0008-2024 | B17: Jembatan | C17: Jakarta | D17: Pembuatan Jembatan Jakarta | E17: 45330 | F17: 45386 | G17: 921085536 | H17: PT B
A18: CN-0009-2023 | B18: Jalan Raya | C18: Jakarta | D18: Perbaikan Jalan Raya Jakarta | E18: 44930 | F18: 45182 | G18: 241214887 | H18: PT B
... A29: CN-0014-2024 | B29: Jalan Raya | C29: Surabaya | D29: Perbaikan Jalan Raya Surabaya | E29: 45339 | F29: 45379 | G29: 545662746 | H29: PT A
A30: CN-0015-2023 | B30: Jalan Raya | C30: Medan | D30: Perbaikan Jalan Raya Medan | E30: 44938 | F30: 44985 | G30: 486357978
A31: CN-0015-2024 | B31: Jalan Raya | C31: Surabaya | D31: Perbaikan Jalan Raya Surabaya | E31: 45340 | F31: 45371 | G31: 810414368 | H31: PT C
A32: CN-0016-2023 | B32: Jalan Raya | C32: Tomohon | D32: Perbaikan Jalan Raya Tomohon | E32: 44938 | F32: 45262 | G32: 341929482 | H32: PT. Yuniar Hakim Tbk
A33: CN-0016-2024 | B33: Jalan Raya | C33: Bau-Bau | D33: Perbaikan Jalan Raya Bau-Bau | E33: 45341 | F33: 45388 | G33: 599466235 | H33: PT. Yuniar Hakim Tbk
A34: CN-0017-2023 | B34: Gedung | C34: Tomohon | D34: Perbaikan Gedung Pemerintah Tomohon | E34: 44939 | F34: 45185 | G34: 4929333305 | H34: PT. Yuniar Hakim Tbk
A35: CN-0017-2024 | B35: Drainase | C35: Bandung | D35: Perbaikan Drainase Bandung | E35: 45341 | F35: 45350 | G35: 333089653 | H35: PT B
A36: CN-0018-2023 | B36: Drainase | C36: Tomohon | D36: Perbaikan Drainase Tomohon | E36: 44940 | F36: 45043 | G36: 523689841 | H36: PT D
A37: CN-0018-2024 | B37: Flyover | C37: Bandung | D37: Pembuatan Flyover Bandung | E37: 45341 | F37: 45406 | G37: 3757312666 | H37: PT B
A38: CN-0019-2023 | B38: Flyover | C38: Medan | D38: Pembuatan Flyover Medan | E38: 44940 | F38: 45206 | G38: 3894709817 | H38: PT. Yuniar Hakim Tbk
A39: CN-0019-2024 | B39: Jalan Raya | C39: Depok | D39: Perbaikan Jalan Raya Depok | E39: 45343 | F39: 45382 | G39: 462876320
A40: CN-0020-2023 | B40: Jembatan | C40: Jakarta | D40: Pembuatan Jembatan Jakarta | E40: 44941 | F40: 45188 | G40: 4532376815 | H40: PT D
A41: CN-0020-2024 | B41: Jembatan | C41: Depok | D41: Pembuatan Jembatan Depok | E41: 45346 | F41: 45398 | G41: 3821117140 | H41: PT D
A42: CN-0021-2023 | B42: Flyover | C42: Bau-Bau | D42: Perbaikan Flyover Bau-Bau | E42: 44941 | F42: 45290 | G42: 4159855566 | H42: PT C
A43: CN-0022-2023 | B43: Jembatan | C43: Bandung | D43: Perbaikan Jembatan Bandung | E43: 44941 | F43: 45095 | G43: 4492886828 | H43: PT D
A44: CN-0023-2023 | B44: Jembatan | C44: Surabaya | D44: Pembuatan Jembatan Surabaya | E44: 44942 | F44: 45034 | G44: 1424729417 | H44: PT. Yuniar Hakim Tbk
A45: CN-0024-2023 | B45: Jembatan | C45: Bau-Bau | D45: Pembuatan Jembatan Bau-Bau | E45: 44943 | F45: 45027 | G45: 1425616276 | H45: CV Sihombing
A46: CN-0025-2023 | B46: Jalan Raya | C46: Bandung | D46: Perbaikan Jalan Raya Bandung | E46: 44943 | F46: 45136 | G46: 307413755 | H46: CV Sihombing
A47: CN-0026-2023 | B47: Jembatan | C47: Bau-Bau | D47: Pembuatan Jembatan Bau-Bau | E47: 44944 | F47: 45113 | G47: 6929733135 | H47: PT C
A48: CN-0027-2023 | B48: Jembatan | C48: Bau-Bau | D48: Perbaikan Jembatan Bau-Bau | E48: 44944 | F48: 45284 | G48: 1567712170 | H48: PT. Yuniar Hakim Tbk
A49: CN-0028-2023 | B49: Jembatan | C49: Jakarta | D49: Pembuatan Jembatan Jakarta | E49: 44945 | F49: 45037 | G49: 3020860458 | H49: PT. Yuniar Hakim Tbk
A50: CN-0029-2023 | B50: Drainase | C50: Medan | D50: Perbaikan Drainase Medan | E50: 44946 | F50: 45105 | G50: 443234047 | H50: PT. Lailasari Hariyah (Persero) Tbk
...

Sheet Data Cleaning
A1: ID_Proyek | B1: Jenis_Proyek | C1: Lokasi | D1: Nama_Proyek | E1: Tanggal_Mulai | F1: Tanggal_Selesai | G1: Anggaran | H1: Kontraktor | J1: Cek validasi tanggal | K1: Cek validai anggaran
A2: CN-0001-2023 | B2: =TRIM('Raw Dataset'!B2) -> Drainase | C2: =TRIM('Raw Dataset'!C2) -> Bandung | D2: =TRIM('Raw Dataset'!D2) -> Perbaikan Drainase Bandung | E2: 44927 | F2: 44994 | G2: 649208256 | H2: =TRIM('Raw Dataset'!H2) -> PT. Lailasari Hariyah (Persero) Tbk | J2: {=IF(Table2[Tanggal_Selesai] < Table2[Tanggal_Mulai],"ERROR","OK")} -> OK | K2: {=IF(Table2[Anggaran] <= 0, "ERROR", "OK")} -> OK
A3: CN-0001-2024 | B3: =TRIM('Raw Dataset'!B3) -> Drainase | C3: =TRIM('Raw Dataset'!C3) -> Surabaya | D3: =TRIM('Raw Dataset'!D3) -> Perbaikan Drainase Surabaya | E3: 45319 | F3: 45323 | G3: 326999652 | H3: =TRIM('Raw Dataset'!H3) -> CV Sihombing | J3: OK | K3: OK
A4: CN-0002-2023 | B4: =TRIM('Raw Dataset'!B4) -> Flyover | C4: =TRIM('Raw Dataset'!C4) -> Depok | D4: =TRIM('Raw Dataset'!D4) -> Pembuatan Flyover Depok | E4: 44927 | F4: 45062 | G4: 3474309188 | H4: =TRIM('Raw Dataset'!H4) -> CV Sihombing | J4: OK | K4: OK
A5: CN-0002-2024 | B5: =TRIM('Raw Dataset'!B5) -> Gedung | C5: =TRIM('Raw Dataset'!C5) -> Jakarta | D5: =TRIM('Raw Dataset'!D5) -> Perbaikan Gedung Pemerintah Jakarta | E5: 45320 | F5: 45336 | G5: 8587951510 | H5: =TRIM('Raw Dataset'!H5) -> CV Sihombing | J5: OK | K5: OK
A6: CN-0003-2023 | B6: =TRIM('Raw Dataset'!B6) -> Jalan Raya | C6: =TRIM('Raw Dataset'!C6) -> Bandung | D6: =TRIM('Raw Dataset'!D6) -> Perbaikan Jalan Raya Bandung | E6: 44928 | F6: 45239 | G6: 191505827 | H6: =TRIM('Raw Dataset'!H6) | J6: OK | K6: OK
A7: CN-0003-2024 | B7: =TRIM('Raw Dataset'!B7) -> Gedung | C7: =TRIM('Raw Dataset'!C7) -> Tomohon | D7: =TRIM('Raw Dataset'!D7) -> Perbaikan Gedung Pemerintah Tomohon | E7: 45323 | F7: 45343 | G7: 8016851785 | H7: =TRIM('Raw Dataset'!H7) -> PT. Yuniar Hakim Tbk | J7: OK | K7: OK
A8: CN-0004-2023 | B8: =TRIM('Raw Dataset'!B8) -> Flyover | C8: =TRIM('Raw Dataset'!C8) -> Tomohon | D8: =TRIM('Raw Dataset'!D8) -> Pembuatan Flyover Tomohon | E8: 44928 | F8: 45006 | G8: 3979021821 | H8: =TRIM('Raw Dataset'!H8) -> PT D | J8: OK | K8: OK
A9: CN-0004-2024 | B9: =TRIM('Raw Dataset'!B9) -> Gedung | C9: =TRIM('Raw Dataset'!C9) -> Jakarta | D9: =TRIM('Raw Dataset'!D9) -> Perbaikan Gedung Pemerintah Jakarta | E9: 45325 | F9: 45342 | G9: 2153093275 | H9: =TRIM('Raw Dataset'!H9) -> PT. Yuniar Hakim Tbk | J9: OK | K9: OK
A10: CN-0005-2023 | B10: =TRIM('Raw Dataset'!B10) -> Drainase | C10: =TRIM('Raw Dataset'!C10) -> Jakarta | D10: =TRIM('Raw Dataset'!D10) -> Perbaikan Drainase Jakarta | E10: 44928 | F10: 45271 | G10: 683556997 | H10: =TRIM('Raw Dataset'!H10) -> PT A | J10: OK | K10: OK
A11: CN-0005-2024 | B11: =TRIM('Raw Dataset'!B11) -> Jembatan | C11: =TRIM('Raw Dataset'!C11) -> Bau-Bau | D11: =TRIM('Raw Dataset'!D11) -> Perbaikan Jembatan Bau-Bau | E11: 45327 | F11: 45353 | G11: 4636324090 | H11: =TRIM('Raw Dataset'!H11) -> PT. Lailasari Hariyah (Persero) Tbk | J11: OK | K11: OK
A12: CN-0006-2023 | B12: =TRIM('Raw Dataset'!B12) -> Drainase | C12: =TRIM('Raw Dataset'!C12) -> Tomohon | D12: =TRIM('Raw Dataset'!D12) -> Perbaikan Drainase Tomohon | E12: 44929 | F12: 45230 | G12: 663835414 | H12: =TRIM('Raw Dataset'!H12) -> PT B | J12: OK | K12: OK
A13: CN-0006-2024 | B13: =TRIM('Raw Dataset'!B13) -> Drainase | C13: =TRIM('Raw Dataset'!C13) -> Bandung | D13: =TRIM('Raw Dataset'!D13) -> Perbaikan Drainase Bandung | E13: 45329 | F13: 45360 | G13: 698540517 | H13: =TRIM('Raw Dataset'!H13) -> PT A | J13: OK | K13: OK
A14: CN-0007-2023 | B14: =TRIM('Raw Dataset'!B14) -> Flyover | C14: =TRIM('Raw Dataset'!C14) -> Medan | D14: =TRIM('Raw Dataset'!D14) -> Pembuatan Flyover Medan | E14: 44929 | F14: 45261 | G14: 2423693734 | H14: =TRIM('Raw Dataset'!H14) -> PT D | J14: OK | K14: OK
... A78: CN-0057-2023 | B78: =TRIM('Raw Dataset'!B78) -> Jalan Raya | C78: =TRIM('Raw Dataset'!C78) -> Depok | D78: =TRIM('Raw Dataset'!D78) -> Perbaikan Jalan Raya Depok | E78: 44969 | F78: 45123 | G78: 926922328 | H78: =TRIM('Raw Dataset'!H78) -> PT C | J78: OK | K78: OK
A79: CN-0058-2023 | E79: 44969 | F79: 45030 | G79: 314690070 | H79: =TRIM('Raw Dataset'!H79) -> CV Sihombing | J79: OK | K79: OK
A80: CN-0059-2023 | B80: Drainase | C80: Surabaya | D80: Perbaikan Drainase Surabaya | E80: 44971 | F80: 45232 | G80: 708312743 | H80: =TRIM('Raw Dataset'!H80) -> PT D | J80: OK | K80: OK
A81: CN-0060-2023 | B81: Drainase | C81: Medan | D81: Perbaikan Drainase Medan | E81: 44971 | F81: 45228 | G81: 419037113 | H81: =TRIM('Raw Dataset'!H81) -> PT A | J81: OK | K81: OK
A82: CN-0061-2023 | B82: Drainase | C82: Jakarta | D82: Perbaikan Drainase Jakarta | E82: 44972 | F82: 45130 | G82: 500841363 | H82: =TRIM('Raw Dataset'!H82) -> PT. Yuniar Hakim Tbk | J82: OK | K82: OK
A83: CN-0062-2023 | B83: Jalan Raya | C83: Jakarta | D83: Perbaikan Jalan Raya Jakarta | E83: 44973 | F83: 45289 | G83: 209304110 | H83: =TRIM('Raw Dataset'!H83) -> PT. Yuniar Hakim Tbk | J83: OK | K83: OK
A84: CN-0063-2023 | B84: Jembatan | C84: Medan | D84: Perbaikan Jembatan Medan | E84: 44974 | F84: 45082 | G84: 3686469051 | H84: =TRIM('Raw Dataset'!H84) -> PT. Yuniar Hakim Tbk | J84: OK | K84: OK
A85: CN-0064-2023 | B85: Jalan Raya | C85: Bandung | D85: Perbaikan Jalan Raya Bandung | E85: 44974 | F85: 45112 | G85: 353290709 | H85: =TRIM('Raw Dataset'!H85) -> PT. Lailasari Hariyah (Persero) Tbk | J85: OK | K85: OK
A86: CN-0065-2023 | B86: Gedung | C86: Jakarta | D86: Perbaikan Gedung Pemerintah Jakarta | E86: 44974 | F86: 45230 | G86: 8935017863 | H86: =TRIM('Raw Dataset'!H86) -> PT A | J86: OK | K86: OK
A87: CN-0066-2023 | B87: Jembatan | C87: Bau-Bau | D87: Perbaikan Jembatan Bau-Bau | E87: 44975 | F87: 45193 | G87: 5518454926 | H87: =TRIM('Raw Dataset'!H87) -> PT C | J87: OK | K87: OK
A88: CN-0067-2023 | B88: Flyover | C88: Medan | D88: Perbaikan Flyover Medan | E88: 44975 | F88: 45256 | G88: 3367495384 | H88: =TRIM('Raw Dataset'!H88) | J88: OK | K88: OK
A89: CN-0068-2023 | B89: Flyover | C89: Bandung | D89: Perbaikan Flyover Bandung | E89: 44976 | F89: 45307 | G89: 2293993253 | H89: =TRIM('Raw Dataset'!H89) -> PT C | J89: OK | K89: OK
A90: CN-0069-2023 | B90: Flyover | C90: Makassar | D90: Pembuatan Flyover Makassar | E90: 44976 | F90: 45318 | G90: 1790927128 | H90: =TRIM('Raw Dataset'!H90) -> PT D | J90: OK | K90: OK
A91: CN-0070-2023 | B91: Gedung | C91: Jakarta | E91: 44977 | F91: 45285 | G91: 7432359735 | H91: =TRIM('Raw Dataset'!H91) | J91: OK | K91: OK
A92: CN-0071-2023 | B92: Gedung | C92: Surabaya | D92: Perbaikan Gedung Pemerintah Surabaya | E92: 44977 | F92: 45233 | G92: 7645065116 | H92: =TRIM('Raw Dataset'!H92) | J92: OK | K92: OK
A93: CN-0072-2023 | B93: Jembatan | C93: Tomohon | D93: Perbaikan Jembatan Tomohon | E93: 44979 | F93: 45295 | G93: 5522312320 | H93: =TRIM('Raw Dataset'!H93) -> PT. Yuniar Hakim Tbk | J93: OK | K93: OK
A94: CN-0073-2023 | B94: Jalan Raya | C94: Medan | D94: Perbaikan Jalan Raya Medan | E94: 44979 | F94: 45074 | G94: 934325560 | H94: =TRIM('Raw Dataset'!H94) -> PT D | J94: OK | K94: OK
A95: CN-0074-2023 | B95: Jalan Raya | C95: Makassar | D95: Perbaikan Jalan Raya Makassar | E95: 44979 | F95: 45058 | G95: 121142623 | H95: =TRIM('Raw Dataset'!H95) -> CV Sihombing | J95: OK | K95: OK
A96: CN-0075-2023 | B96: Jembatan | C96: Medan | D96: Pembuatan Jembatan Medan | E96: 44982 | F96: 45181 | G96: 1493231996 | H96: =TRIM('Raw Dataset'!H96) -> PT C | J96: OK | K96: OK
A97: CN-0076-2023 | B97: Jembatan | C97: Jakarta | D97: Pembuatan Jembatan Jakarta | E97: 44984 | F97: 45324 | G97: 5860997586 | H97: =TRIM('Raw Dataset'!H97) -> PT. Lailasari Hariyah (Persero) Tbk | J97: OK | K97: OK
A98: CN-0077-2023 | B98: Drainase | C98: Jakarta | D98: Perbaikan Drainase Jakarta | E98: 44984 | F98: 45149 | G98: 551513519 | H98: =TRIM('Raw Dataset'!H98) -> CV Sihombing | J98: OK | K98: OK
A99: CN-0078-2023 | B99: Jalan Raya | C99: Surabaya | D99: Perbaikan Jalan Raya Surabaya | E99: 44985 | F99: 45186 | G99: 359783228 | H99: =TRIM('Raw Dataset'!H99) -> CV Sihombing | J99: OK | K99: OK
A100: CN-0079-2023 | B100: Flyover | C100: Surabaya | D100: Perbaikan Flyover Surabaya | E100: 44986 | F100: 45105 | G100: 4429242773 | H100: =TRIM('Raw Dataset'!H100) -> PT D | J100: OK | K100: OK
A101: CN-0080-2023 | B101: Gedung | C101: Tomohon | D101: Perbaikan Gedung Pemerintah Tomohon | E101: 44987 | F101: 45234 | G101: 2034415367 | H101: =TRIM('Raw Dataset'!H101) -> PT B | J101: OK | K101: OK
A102: CN-0081-2023 | B102: Jembatan | C102: Medan | D102: Perbaikan Jembatan Medan | E102: 44989 | F102: 45301 | G102: 1597122511 | H102: =TRIM('Raw Dataset'!H102) -> CV Sihombing | J102: OK | K102: OK
A103: CN-0082-2023 | B103: Jalan Raya | C103: Medan | D103: Perbaikan Jalan Raya Medan | E103: 44989 | F103: 45120 | G103: 966519099 | H103: =TRIM('Raw Dataset'!H103) -> PT C | J103: OK | K103: OK
...

Sheet Null Data
A1: ID_Proyek | B1: Jenis_Proyek | C1: Lokasi | D1: Nama_Proyek | E1: Tanggal_Mulai | F1: Tanggal_Selesai | G1: Anggaran | H1: Kontraktor
A2: CN-0001-2023 | B2: =IF(Table2[[#This Row],[Jenis_Proyek]]="", "Tidak Diketahui", Table2[[#This Row],[Jenis_Proyek]]) -> Drainase | C2: =IF(Table2[[#This Row],[Lokasi]]="", "Tidak Diketahui", Table2[[#This Row],[Lokasi]]) -> Bandung | D2: =IF(Table2[[#This Row],[Nama_Proyek]]="", "Tidak Diketahui", Table2[[#This Row],[Nama_Proyek]]) -> Perbaikan Drainase Bandung | E2: 44927 | F2: 44994 | G2: 649208256 | H2: =IF(Table2[[#This Row],[Kontraktor]]="", "Tidak Diketahui",Table2[[#This Row],[Kontraktor]]) -> PT. Lailasari Hariyah (Persero) Tbk
A3: CN-0001-2024 | B3: =IF(Table2[[#This Row],[Jenis_Proyek]]="", "Tidak Diketahui", Table2[[#This Row],[Jenis_Proyek]]) -> Drainase | C3: =IF(Table2[[#This Row],[Lokasi]]="", "Tidak Diketahui", Table2[[#This Row],[Lokasi]]) -> Surabaya | D3: =IF(Table2[[#This Row],[Nama_Proyek]]="", "Tidak Diketahui", Table2[[#This Row],[Nama_Proyek]]) -> Perbaikan Drainase Surabaya | E3: 45319 | F3: 45323 | G3: 326999652 | H3: =IF(Table2[[#This Row],[Kontraktor]]="", "Tidak Diketahui",Table2[[#This Row],[Kontraktor]]) -> CV Sihombing
A4: CN-0002-2023 | B4: =IF(Table2[[#This Row],[Jenis_Proyek]]="", "Tidak Diketahui", Table2[[#This Row],[Jenis_Proyek]]) -> Flyover | C4: =IF(Table2[[#This Row],[Lokasi]]="", "Tidak Diketahui", Table2[[#This Row],[Lokasi]]) -> Depok | D4: =IF(Table2[[#This Row],[Nama_Proyek]]="", "Tidak Diketahui", Table2[[#This Row],[Nama_Proyek]]) -> Pembuatan Flyover Depok | E4: 44927 | F4: 45062 | G4: 3474309188 | H4: =IF(Table2[[#This Row],[Kontraktor]]="", "Tidak Diketahui",Table2[[#This Row],[Kontraktor]]) -> CV Sihombing
A5: CN-0002-2024 | B5: =IF(Table2[[#This Row],[Jenis_Proyek]]="", "Tidak Diketahui", Table2[[#This Row],[Jenis_Proyek]]) -> Gedung | C5: =IF(Table2[[#This Row],[Lokasi]]="", "Tidak Diketahui", Table2[[#This Row],[Lokasi]]) -> Jakarta | D5: =IF(Table2[[#This Row],[Nama_Proyek]]="", "Tidak Diketahui", Table2[[#This Row],[Nama_Proyek]]) -> Perbaikan Gedung Pemerintah Jakarta | E5: 45320 | F5: 45336 | G5: 8587951510 | H5: =IF(Table2[[#This Row],[Kontraktor]]="", "Tidak Diketahui",Table2[[#This Row],[Kontraktor]]) -> CV Sihombing
A6: CN-0003-2023 | B6: =IF(Table2[[#This Row],[Jenis_Proyek]]="", "Tidak Diketahui", Table2[[#This Row],[Jenis_Proyek]]) -> Jalan Raya | C6: =IF(Table2[[#This Row],[Lokasi]]="", "Tidak Diketahui", Table2[[#This Row],[Lokasi]]) -> Bandung | D6: =IF(Table2[[#This Row],[Nama_Proyek]]="", "Tidak Diketahui", Table2[[#This Row],[Nama_Proyek]]) -> Perbaikan Jalan Raya Bandung | E6: 44928 | F6: 45239 | G6: 191505827 | H6: =IF(Table2[[#This Row],[Kontraktor]]="", "Tidak Diketahui",Table2[[#This Row],[Kontraktor]]) -> Tidak Diketahui
A7: CN-0003-2024 | B7: =IF(Table2[[#This Row],[Jenis_Proyek]]="", "Tidak Diketahui", Table2[[#This Row],[Jenis_Proyek]]) -> Gedung | C7: =IF(Table2[[#This Row],[Lokasi]]="", "Tidak Diketahui", Table2[[#This Row],[Lokasi]]) -> Tomohon | D7: =IF(Table2[[#This Row],[Nama_Proyek]]="", "Tidak Diketahui", Table2[[#This Row],[Nama_Proyek]]) -> Perbaikan Gedung Pemerintah Tomohon | E7: 45323 | F7: 45343 | G7: 8016851785 | H7: =IF(Table2[[#This Row],[Kontraktor]]="", "Tidak Diketahui",Table2[[#This Row],[Kontraktor]]) -> PT. Yuniar Hakim Tbk
A8: CN-0004-2023 | B8: =IF(Table2[[#This Row],[Jenis_Proyek]]="", "Tidak Diketahui", Table2[[#This Row],[Jenis_Proyek]]) -> Flyover | C8: =IF(Table2[[#This Row],[Lokasi]]="", "Tidak Diketahui", Table2[[#This Row],[Lokasi]]) -> Tomohon | D8: =IF(Table2[[#This Row],[Nama_Proyek]]="", "Tidak Diketahui", Table2[[#This Row],[Nama_Proyek]]) -> Pembuatan Flyover Tomohon | E8: 44928 | F8: 45006 | G8: 3979021821 | H8: =IF(Table2[[#This Row],[Kontraktor]]="", "Tidak Diketahui",Table2[[#This Row],[Kontraktor]]) -> PT D
A9: CN-0004-2024 | B9: =IF(Table2[[#This Row],[Jenis_Proyek]]="", "Tidak Diketahui", Table2[[#This Row],[Jenis_Proyek]]) -> Gedung | C9: =IF(Table2[[#This Row],[Lokasi]]="", "Tidak Diketahui", Table2[[#This Row],[Lokasi]]) -> Jakarta | D9: =IF(Table2[[#This Row],[Nama_Proyek]]="", "Tidak Diketahui", Table2[[#This Row],[Nama_Proyek]]) -> Perbaikan Gedung Pemerintah Jakarta | E9: 45325 | F9: 45342 | G9: 2153093275 | H9: =IF(Table2[[#This Row],[Kontraktor]]="", "Tidak Diketahui",Table2[[#This Row],[Kontraktor]]) -> PT. Yuniar Hakim Tbk
A10: CN-0005-2023 | B10: =IF(Table2[[#This Row],[Jenis_Proyek]]="", "Tidak Diketahui", Table2[[#This Row],[Jenis_Proyek]]) -> Drainase | C10: =IF(Table2[[#This Row],[Lokasi]]="", "Tidak Diketahui", Table2[[#This Row],[Lokasi]]) -> Jakarta | D10: =IF(Table2[[#This Row],[Nama_Proyek]]="", "Tidak Diketahui", Table2[[#This Row],[Nama_Proyek]]) -> Perbaikan Drainase Jakarta | E10: 44928 | F10: 45271 | G10: 683556997 | H10: =IF(Table2[[#This Row],[Kontraktor]]="", "Tidak Diketahui",Table2[[#This Row],[Kontraktor]]) -> PT A
A11: CN-0005-2024 | B11: =IF(Table2[[#This Row],[Jenis_Proyek]]="", "Tidak Diketahui", Table2[[#This Row],[Jenis_Proyek]]) -> Jembatan | C11: =IF(Table2[[#This Row],[Lokasi]]="", "Tidak Diketahui", Table2[[#This Row],[Lokasi]]) -> Bau-Bau | D11: =IF(Table2[[#This Row],[Nama_Proyek]]="", "Tidak Diketahui", Table2[[#This Row],[Nama_Proyek]]) -> Perbaikan Jembatan Bau-Bau | E11: 45327 | F11: 45353 | G11: 4636324090 | H11: =IF(Table2[[#This Row],[Kontraktor]]="", "Tidak Diketahui",Table2[[#This Row],[Kontraktor]]) -> PT. Lailasari Hariyah (Persero) Tbk
A12: CN-0006-2023 | B12: =IF(Table2[[#This Row],[Jenis_Proyek]]="", "Tidak Diketahui", Table2[[#This Row],[Jenis_Proyek]]) -> Drainase | C12: =IF(Table2[[#This Row],[Lokasi]]="", "Tidak Diketahui", Table2[[#This Row],[Lokasi]]) -> Tomohon | D12: =IF(Table2[[#This Row],[Nama_Proyek]]="", "Tidak Diketahui", Table2[[#This Row],[Nama_Proyek]]) -> Perbaikan Drainase Tomohon | E12: 44929 | F12: 45230 | G12: 663835414 | H12: =IF(Table2[[#This Row],[Kontraktor]]="", "Tidak Diketahui",Table2[[#This Row],[Kontraktor]]) -> PT B
A13: CN-0006-2024 | B13: =IF(Table2[[#This Row],[Jenis_Proyek]]="", "Tidak Diketahui", Table2[[#This Row],[Jenis_Proyek]]) -> Drainase | C13: =IF(Table2[[#This Row],[Lokasi]]="", "Tidak Diketahui", Table2[[#This Row],[Lokasi]]) -> Bandung | D13: =IF(Table2[[#This Row],[Nama_Proyek]]="", "Tidak Diketahui", Table2[[#This Row],[Nama_Proyek]]) -> Perbaikan Drainase Bandung | E13: 45329 | F13: 45360 | G13: 698540517 | H13: =IF(Table2[[#This Row],[Kontraktor]]="", "Tidak Diketahui",Table2[[#This Row],[Kontraktor]]) -> PT A
... A500: CN-0479-2023 | B500: =IF(Table2[[#This Row],[Jenis_Proyek]]="", "Tidak Diketahui", Table2[[#This Row],[Jenis_Proyek]]) -> Gedung | C500: =IF(Table2[[#This Row],[Lokasi]]="", "Tidak Diketahui", Table2[[#This Row],[Lokasi]]) -> Surabaya | D500: =IF(Table2[[#This Row],[Nama_Proyek]]="", "Tidak Diketahui", Table2[[#This Row],[Nama_Proyek]]) -> Perbaikan Gedung Pemerintah Surabaya | E500: 45291 | F500: 45563 | G500: 2974669932 | H500: =IF(Table2[[#This Row],[Kontraktor]]="", "Tidak Diketahui",Table2[[#This Row],[Kontraktor]]) -> PT B

Sheet Feature Engineering
A1: ID_Proyek | B1: Jenis_Proyek | C1: Lokasi | D1: Nama_Proyek | E1: Tanggal_Mulai | F1: Tanggal_Selesai | G1: Anggaran | H1: Kontraktor | I1: Durasi_Proyek | J1: Efisiensi Kontraktor | K1: Tahun_Mulai
A2: CN-0001-2023 | B2: =IF(Table2[[#This Row],[Jenis_Proyek]]="", "Tidak Diketahui", Table2[[#This Row],[Jenis_Proyek]]) -> Drainase | C2: =IF(Table2[[#This Row],[Lokasi]]="", "Tidak Diketahui", Table2[[#This Row],[Lokasi]]) -> Bandung | D2: =IF(Table2[[#This Row],[Nama_Proyek]]="", "Tidak Diketahui", Table2[[#This Row],[Nama_Proyek]]) -> Perbaikan Drainase Bandung | E2: 44927 | F2: 44994 | G2: 649208256 | H2: =IF(Table2[[#This Row],[Kontraktor]]="", "Tidak Diketahui",Table2[[#This Row],[Kontraktor]]) -> PT. Lailasari Hariyah (Persero) Tbk | I2: =Table245[[#This Row],[Tanggal_Selesai]]-Table245[[#This Row],[Tanggal_Mulai]] -> 67 | J2: =Table245[[#This Row],[Anggaran]]/Table245[[#This Row],[Durasi_Proyek]] -> 9689675.5 | K2: =YEAR(Table245[[#This Row],[Tanggal_Mulai]]) -> 2023
A3: CN-0001-2024 | B3: =IF(Table2[[#This Row],[Jenis_Proyek]]="", "Tidak Diketahui", Table2[[#This Row],[Jenis_Proyek]]) -> Drainase | C3: =IF(Table2[[#This Row],[Lokasi]]="", "Tidak Diketahui", Table2[[#This Row],[Lokasi]]) -> Surabaya | D3: =IF(Table2[[#This Row],[Nama_Proyek]]="", "Tidak Diketahui", Table2[[#This Row],[Nama_Proyek]]) -> Perbaikan Drainase Surabaya | E3: 45319 | F3: 45323 | G3: 326999652 | H3: =IF(Table2[[#This Row],[Kontraktor]]="", "Tidak Diketahui",Table2[[#This Row],[Kontraktor]]) -> CV Sihombing | I3: =Table245[[#This Row],[Tanggal_Selesai]]-Table245[[#This Row],[Tanggal_Mulai]] -> 4 | J3: =Table245[[#This Row],[Anggaran]]/Table245[[#This Row],[Durasi_Proyek]] -> 81749913 | K3: =YEAR(Table245[[#This Row],[Tanggal_Mulai]]) -> 2024
A4: CN-0002-2023 | B4: =IF(Table2[[#This Row],[Jenis_Proyek]]="", "Tidak Diketahui", Table2[[#This Row],[Jenis_Proyek]]) -> Flyover | C4: =IF(Table2[[#This Row],[Lokasi]]="", "Tidak Diketahui", Table2[[#This Row],[Lokasi]]) -> Depok | D4: =IF(Table2[[#This Row],[Nama_Proyek]]="", "Tidak Diketahui", Table2[[#This Row],[Nama_Proyek]]) -> Pembuatan Flyover Depok | E4: 44927 | F4: 45062 | G4: 3474309188 | H4: =IF(Table2[[#This Row],[Kontraktor]]="", "Tidak Diketahui",Table2[[#This Row],[Kontraktor]]) -> CV Sihombing | I4: =Table245[[#This Row],[Tanggal_Selesai]]-Table245[[#This Row],[Tanggal_Mulai]] -> 135 | J4: =Table245[[#This Row],[Anggaran]]/Table245[[#This Row],[Durasi_Proyek]] -> 25735624 | K4: =YEAR(Table245[[#This Row],[Tanggal_Mulai]]) -> 2023
A5: CN-0002-2024 | B5: =IF(Table2[[#This Row],[Jenis_Proyek]]="", "Tidak Diketahui", Table2[[#This Row],[Jenis_Proyek]]) -> Gedung | C5: =IF(Table2[[#This Row],[Lokasi]]="", "Tidak Diketahui", Table2[[#This Row],[Lokasi]]) -> Jakarta | D5: =IF(Table2[[#This Row],[Nama_Proyek]]="", "Tidak Diketahui", Table2[[#This Row],[Nama_Proyek]]) -> Perbaikan Gedung Pemerintah Jakarta | E5: 45320 | F5: 45336 | G5: 8587951510 | H5: =IF(Table2[[#This Row],[Kontraktor]]="", "Tidak Diketahui",Table2[[#This Row],[Kontraktor]]) -> CV Sihombing | I5: =Table245[[#This Row],[Tanggal_Selesai]]-Table245[[#This Row],[Tanggal_Mulai]] -> 16 | J5: =Table245[[#This Row],[Anggaran]]/Table245[[#This Row],[Durasi_Proyek]] -> 5.3674697e+08 | K5: =YEAR(Table245[[#This Row],[Tanggal_Mulai]]) -> 2024
A6: CN-0003-2023 | B6: =IF(Table2[[#This Row],[Jenis_Proyek]]="", "Tidak Diketahui", Table2[[#This Row],[Jenis_Proyek]]) -> Jalan Raya | C6: =IF(Table2[[#This Row],[Lokasi]]="", "Tidak Diketahui", Table2[[#This Row],[Lokasi]]) -> Bandung | D6: =IF(Table2[[#This Row],[Nama_Proyek]]="", "Tidak Diketahui", Table2[[#This Row],[Nama_Proyek]]) -> Perbaikan Jalan Raya Bandung | E6: 44928 | F6: 45239 | G6: 191505827 | H6: =IF(Table2[[#This Row],[Kontraktor]]="", "Tidak Diketahui",Table2[[#This Row],[Kontraktor]]) -> Tidak Diketahui | I6: =Table245[[#This Row],[Tanggal_Selesai]]-Table245[[#This Row],[Tanggal_Mulai]] -> 311 | J6: =Table245[[#This Row],[Anggaran]]/Table245[[#This Row],[Durasi_Proyek]] -> 615774.36 | K6: =YEAR(Table245[[#This Row],[Tanggal_Mulai]]) -> 2023
A7: CN-0003-2024 | B7: =IF(Table2[[#This Row],[Jenis_Proyek]]="", "Tidak Diketahui", Table2[[#This Row],[Jenis_Proyek]]) -> Gedung | C7: =IF(Table2[[#This Row],[Lokasi]]="", "Tidak Diketahui", Table2[[#This Row],[Lokasi]]) -> Tomohon | D7: =IF(Table2[[#This Row],[Nama_Proyek]]="", "Tidak Diketahui", Table2[[#This Row],[Nama_Proyek]]) -> Perbaikan Gedung Pemerintah Tomohon | E7: 45323 | F7: 45343 | G7: 8016851785 | H7: =IF(Table2[[#This Row],[Kontraktor]]="", "Tidak Diketahui",Table2[[#This Row],[Kontraktor]]) -> PT. Yuniar Hakim Tbk | I7: =Table245[[#This Row],[Tanggal_Selesai]]-Table245[[#This Row],[Tanggal_Mulai]] -> 20 | J7: =Table245[[#This Row],[Anggaran]]/Table245[[#This Row],[Durasi_Proyek]] -> 4.0084259e+08 | K7: =YEAR(Table245[[#This Row],[Tanggal_Mulai]]) -> 2024
A8: CN-0004-2023 | B8: =IF(Table2[[#This Row],[Jenis_Proyek]]="", "Tidak Diketahui", Table2[[#This Row],[Jenis_Proyek]]) -> Flyover | C8: =IF(Table2[[#This Row],[Lokasi]]="", "Tidak Diketahui", Table2[[#This Row],[Lokasi]]) -> Tomohon | D8: =IF(Table2[[#This Row],[Nama_Proyek]]="", "Tidak Diketahui", Table2[[#This Row],[Nama_Proyek]]) -> Pembuatan Flyover Tomohon | E8: 44928 | F8: 45006 | G8: 3979021821 | H8: =IF(Table2[[#This Row],[Kontraktor]]="", "Tidak Diketahui",Table2[[#This Row],[Kontraktor]]) -> PT D | I8: =Table245[[#This Row],[Tanggal_Selesai]]-Table245[[#This Row],[Tanggal_Mulai]] -> 78 | J8: =Table245[[#This Row],[Anggaran]]/Table245[[#This Row],[Durasi_Proyek]] -> 51013100 | K8: =YEAR(Table245[[#This Row],[Tanggal_Mulai]]) -> 2023
A9: CN-0004-2024 | B9: =IF(Table2[[#This Row],[Jenis_Proyek]]="", "Tidak Diketahui", Table2[[#This Row],[Jenis_Proyek]]) -> Gedung | C9: =IF(Table2[[#This Row],[Lokasi]]="", "Tidak Diketahui", Table2[[#This Row],[Lokasi]]) -> Jakarta | D9: =IF(Table2[[#This Row],[Nama_Proyek]]="", "Tidak Diketahui", Table2[[#This Row],[Nama_Proyek]]) -> Perbaikan Gedung Pemerintah Jakarta | E9: 45325 | F9: 45342 | G9: 2153093275 | H9: =IF(Table2[[#This Row],[Kontraktor]]="", "Tidak Diketahui",Table2[[#This Row],[Kontraktor]]) -> PT. Yuniar Hakim Tbk | I9: =Table245[[#This Row],[Tanggal_Selesai]]-Table245[[#This Row],[Tanggal_Mulai]] -> 17 | J9: =Table245[[#This Row],[Anggaran]]/Table245[[#This Row],[Durasi_Proyek]] -> 1.2665255e+08 | K9: =YEAR(Table245[[#This Row],[Tanggal_Mulai]]) -> 2024
A10: CN-0005-2023 | B10: =IF(Table2[[#This Row],[Jenis_Proyek]]="", "Tidak Diketahui", Table2[[#This Row],[Jenis_Proyek]]) -> Drainase | C10: =IF(Table2[[#This Row],[Lokasi]]="", "Tidak Diketahui", Table2[[#This Row],[Lokasi]]) -> Jakarta | D10: =IF(Table2[[#This Row],[Nama_Proyek]]="", "Tidak Diketahui", Table2[[#This Row],[Nama_Proyek]]) -> Perbaikan Drainase Jakarta | E10: 44928 | F10: 45271 | G10: 683556997 | H10: =IF(Table2[[#This Row],[Kontraktor]]="", "Tidak Diketahui",Table2[[#This Row],[Kontraktor]]) -> PT A | I10: =Table245[[#This Row],[Tanggal_Selesai]]-Table245[[#This Row],[Tanggal_Mulai]] -> 343 | J10: =Table245[[#This Row],[Anggaran]]/Table245[[#This Row],[Durasi_Proyek]] -> 1992877.5 | K10: =YEAR(Table245[[#This Row],[Tanggal_Mulai]]) -> 2023
A11: CN-0005-2024 | B11: =IF(Table2[[#This Row],[Jenis_Proyek]]="", "Tidak Diketahui", Table2[[#This Row],[Jenis_Proyek]]) -> Jembatan | C11: =IF(Table2[[#This Row],[Lokasi]]="", "Tidak Diketahui", Table2[[#This Row],[Lokasi]]) -> Bau-Bau | D11: =IF(Table2[[#This Row],[Nama_Proyek]]="", "Tidak Diketahui", Table2[[#This Row],[Nama_Proyek]]) -> Perbaikan Jembatan Bau-Bau | E11: 45327 | F11: 45353 | G11: 4636324090 | H11: =IF(Table2[[#This Row],[Kontraktor]]="", "Tidak Diketahui",Table2[[#This Row],[Kontraktor]]) -> PT. Lailasari Hariyah (Persero) Tbk | I11: =Table245[[#This Row],[Tanggal_Selesai]]-Table245[[#This Row],[Tanggal_Mulai]] -> 26 | J11: =Table245[[#This Row],[Anggaran]]/Table245[[#This Row],[Durasi_Proyek]] -> 1.7832016e+08 | K11: =YEAR(Table245[[#This Row],[Tanggal_Mulai]]) -> 2024
A12: CN-0006-2023 | B12: =IF(Table2[[#This Row],[Jenis_Proyek]]="", "Tidak Diketahui", Table2[[#This Row],[Jenis_Proyek]]) -> Drainase | C12: =IF(Table2[[#This Row],[Lokasi]]="", "Tidak Diketahui", Table2[[#This Row],[Lokasi]]) -> Tomohon | D12: =IF(Table2[[#This Row],[Nama_Proyek]]="", "Tidak Diketahui", Table2[[#This Row],[Nama_Proyek]]) -> Perbaikan Drainase Tomohon | E12: 44929 | F12: 45230 | G12: 663835414 | H12: =IF(Table2[[#This Row],[Kontraktor]]="", "Tidak Diketahui",Table2[[#This Row],[Kontraktor]]) -> PT B | I12: =Table245[[#This Row],[Tanggal_Selesai]]-Table245[[#This Row],[Tanggal_Mulai]] -> 301 | J12: =Table245[[#This Row],[Anggaran]]/Table245[[#This Row],[Durasi_Proyek]] -> 2205433.3 | K12: =YEAR(Table245[[#This Row],[Tanggal_Mulai]]) -> 2023
A13: CN-0006-2024 | B13: =IF(Table2[[#This Row],[Jenis_Proyek]]="", "Tidak Diketahui", Table2[[#This Row],[Jenis_Proyek]]) -> Drainase | C13: =IF(Table2[[#This Row],[Lokasi]]="", "Tidak Diketahui", Table2[[#This Row],[Lokasi]]) -> Bandung | D13: =IF(Table2[[#This Row],[Nama_Proyek]]="", "Tidak Diketahui", Table2[[#This Row],[Nama_Proyek]]) -> Perbaikan Drainase Bandung | E13: 45329 | F13: 45360 | G13: 698540517 | H13: =IF(Table2[[#This Row],[Kontraktor]]="", "Tidak Diketahui",Table2[[#This Row],[Kontraktor]]) -> PT A | I13: =Table245[[#This Row],[Tanggal_Selesai]]-Table245[[#This Row],[Tanggal_Mulai]] -> 31 | J13: =Table245[[#This Row],[Anggaran]]/Table245[[#This Row],[Durasi_Proyek]] -> 22533565 | K13: =YEAR(Table245[[#This Row],[Tanggal_Mulai]]) -> 2024
... A22: CN-0011-2023 | B22: =IF(Table2[[#This Row],[Jenis_Proyek]]="", "Tidak Diketahui", Table2[[#This Row],[Jenis_Proyek]]) -> Drainase | C22: =IF(Table2[[#This Row],[Lokasi]]="", "Tidak Diketahui", Table2[[#This Row],[Lokasi]]) -> Depok | D22: =IF(Table2[[#This Row],[Nama_Proyek]]="", "Tidak Diketahui", Table2[[#This Row],[Nama_Proyek]]) -> Perbaikan Drainase Depok | E22: 44931 | F22: 44968 | G22: 536495065 | H22: =IF(Table2[[#This Row],[Kontraktor]]="", "Tidak Diketahui",Table2[[#This Row],[Kontraktor]]) -> CV Sihombing | I22: =Table245[[#This Row],[Tanggal_Selesai]]-Table245[[#This Row],[Tanggal_Mulai]] -> 37 | J22: =Table245[[#This Row],[Anggaran]]/Table245[[#This Row],[Durasi_Proyek]] -> 14499867 | K22: =YEAR(Table245[[#This Row],[Tanggal_Mulai]]) -> 2023
A23: CN-0011-2024 | B23: =IF(Table2[[#This Row],[Jenis_Proyek]]="", "Tidak Diketahui", Table2[[#This Row],[Jenis_Proyek]]) -> Flyover | C23: =IF(Table2[[#This Row],[Lokasi]]="", "Tidak Diketahui", Table2[[#This Row],[Lokasi]]) -> Bandung | D23: =IF(Table2[[#This Row],[Nama_Proyek]]="", "Tidak Diketahui", Table2[[#This Row],[Nama_Proyek]]) -> Pembuatan Flyover Bandung | E23: 45336 | F23: 45336 | G23: 3981092285 | H23: =IF(Table2[[#This Row],[Kontraktor]]="", "Tidak Diketahui",Table2[[#This Row],[Kontraktor]]) -> PT D | I23: 1 | J23: =Table245[[#This Row],[Anggaran]]/Table245[[#This Row],[Durasi_Proyek]] -> 3981092285 | K23: =YEAR(Table245[[#This Row],[Tanggal_Mulai]]) -> 2024
A24: CN-0012-2023 | B24: =IF(Table2[[#This Row],[Jenis_Proyek]]="", "Tidak Diketahui", Table2[[#This Row],[Jenis_Proyek]]) -> Drainase | C24: =IF(Table2[[#This Row],[Lokasi]]="", "Tidak Diketahui", Table2[[#This Row],[Lokasi]]) -> Medan | D24: =IF(Table2[[#This Row],[Nama_Proyek]]="", "Tidak Diketahui", Table2[[#This Row],[Nama_Proyek]]) -> Perbaikan Drainase Medan | E24: 44932 | F24: 45108 | G24: 341629572 | H24: =IF(Table2[[#This Row],[Kontraktor]]="", "Tidak Diketahui",Table2[[#This Row],[Kontraktor]]) -> CV Sihombing | I24: =Table245[[#This Row],[Tanggal_Selesai]]-Table245[[#This Row],[Tanggal_Mulai]] -> 176 | J24: =Table245[[#This Row],[Anggaran]]/Table245[[#This Row],[Durasi_Proyek]] -> 1941077.1 | K24: =YEAR(Table245[[#This Row],[Tanggal_Mulai]]) -> 2023
A25: CN-0012-2024 | B25: =IF(Table2[[#This Row],[Jenis_Proyek]]="", "Tidak Diketahui", Table2[[#This Row],[Jenis_Proyek]]) -> Drainase | C25: =IF(Table2[[#This Row],[Lokasi]]="", "Tidak Diketahui", Table2[[#This Row],[Lokasi]]) -> Tomohon | D25: =IF(Table2[[#This Row],[Nama_Proyek]]="", "Tidak Diketahui", Table2[[#This Row],[Nama_Proyek]]) -> Perbaikan Drainase Tomohon | E25: 45337 | F25: 45342 | G25: 603837273 | H25: =IF(Table2[[#This Row],[Kontraktor]]="", "Tidak Diketahui",Table2[[#This Row],[Kontraktor]]) -> PT B | I25: =Table245[[#This Row],[Tanggal_Selesai]]-Table245[[#This Row],[Tanggal_Mulai]] -> 5 | J25: =Table245[[#This Row],[Anggaran]]/Table245[[#This Row],[Durasi_Proyek]] -> 1.2076745e+08 | K25: =YEAR(Table245[[#This Row],[Tanggal_Mulai]]) -> 2024
A26: CN-0013-2023 | B26: =IF(Table2[[#This Row],[Jenis_Proyek]]="", "Tidak Diketahui", Table2[[#This Row],[Jenis_Proyek]]) -> Flyover | C26: =IF(Table2[[#This Row],[Lokasi]]="", "Tidak Diketahui", Table2[[#This Row],[Lokasi]]) -> Bau-Bau | D26: =IF(Table2[[#This Row],[Nama_Proyek]]="", "Tidak Diketahui", Table2[[#This Row],[Nama_Proyek]]) -> Pembuatan Flyover Bau-Bau | E26: 44935 | F26: 44971 | G26: 4534202846 | H26: =IF(Table2[[#This Row],[Kontraktor]]="", "Tidak Diketahui",Table2[[#This Row],[Kontraktor]]) -> CV Sihombing | I26: =Table245[[#This Row],[Tanggal_Selesai]]-Table245[[#This Row],[Tanggal_Mulai]] -> 36 | J26: =Table245[[#This Row],[Anggaran]]/Table245[[#This Row],[Durasi_Proyek]] -> 1.2595008e+08 | K26: =YEAR(Table245[[#This Row],[Tanggal_Mulai]]) -> 2023
A27: CN-0013-2024 | B27: =IF(Table2[[#This Row],[Jenis_Proyek]]="", "Tidak Diketahui", Table2[[#This Row],[Jenis_Proyek]]) -> Drainase | C27: =IF(Table2[[#This Row],[Lokasi]]="", "Tidak Diketahui", Table2[[#This Row],[Lokasi]]) -> Medan | D27: =IF(Table2[[#This Row],[Nama_Proyek]]="", "Tidak Diketahui", Table2[[#This Row],[Nama_Proyek]]) -> Perbaikan Drainase Medan | E27: 45338 | F27: 45346 | G27: 257898943 | H27: =IF(Table2[[#This Row],[Kontraktor]]="", "Tidak Diketahui",Table2[[#This Row],[Kontraktor]]) -> PT. Yuniar Hakim Tbk | I27: =Table245[[#This Row],[Tanggal_Selesai]]-Table245[[#This Row],[Tanggal_Mulai]] -> 8 | J27: =Table245[[#This Row],[Anggaran]]/Table245[[#This Row],[Durasi_Proyek]] -> 32237368 | K27: =YEAR(Table245[[#This Row],[Tanggal_Mulai]]) -> 2024
A28: CN-0014-2023 | B28: =IF(Table2[[#This Row],[Jenis_Proyek]]="", "Tidak Diketahui", Table2[[#This Row],[Jenis_Proyek]]) -> Drainase | C28: =IF(Table2[[#This Row],[Lokasi]]="", "Tidak Diketahui", Table2[[#This Row],[Lokasi]]) -> Medan | D28: =IF(Table2[[#This Row],[Nama_Proyek]]="", "Tidak Diketahui", Table2[[#This Row],[Nama_Proyek]]) -> Perbaikan Drainase Medan | E28: 44936 | F28: 45295 | G28: 489065831 | H28: =IF(Table2[[#This Row],[Kontraktor]]="", "Tidak Diketahui",Table2[[#This Row],[Kontraktor]]) -> PT A | I28: =Table245[[#This Row],[Tanggal_Selesai]]-Table245[[#This Row],[Tanggal_Mulai]] -> 359 | J28: =Table245[[#This Row],[Anggaran]]/Table245[[#This Row],[Durasi_Proyek]] -> 1362300.4 | K28: =YEAR(Table245[[#This Row],[Tanggal_Mulai]]) -> 2023
A29: CN-0014-2024 | B29: =IF(Table2[[#This Row],[Jenis_Proyek]]="", "Tidak Diketahui", Table2[[#This Row],[Jenis_Proyek]]) -> Jalan Raya | C29: =IF(Table2[[#This Row],[Lokasi]]="", "Tidak Diketahui", Table2[[#This Row],[Lokasi]]) -> Surabaya | D29: =IF(Table2[[#This Row],[Nama_Proyek]]="", "Tidak Diketahui", Table2[[#This Row],[Nama_Proyek]]) -> Perbaikan Jalan Raya Surabaya | E29: 45339 | F29: 45379 | G29: 545662746 | H29: =IF(Table2[[#This Row],[Kontraktor]]="", "Tidak Diketahui",Table2[[#This Row],[Kontraktor]]) -> PT A | I29: =Table245[[#This Row],[Tanggal_Selesai]]-Table245[[#This Row],[Tanggal_Mulai]] -> 40 | J29: =Table245[[#This Row],[Anggaran]]/Table245[[#This Row],[Durasi_Proyek]] -> 13641569 | K29: =YEAR(Table245[[#This Row],[Tanggal_Mulai]]) -> 2024
A30: CN-0015-2023 | B30: =IF(Table2[[#This Row],[Jenis_Proyek]]="", "Tidak Diketahui", Table2[[#This Row],[Jenis_Proyek]]) -> Jalan Raya | C30: =IF(Table2[[#This Row],[Lokasi]]="", "Tidak Diketahui", Table2[[#This Row],[Lokasi]]) -> Medan | D30: =IF(Table2[[#This Row],[Nama_Proyek]]="", "Tidak Diketahui", Table2[[#This Row],[Nama_Proyek]]) -> Perbaikan Jalan Raya Medan | E30: 44938 | F30: 44985 | G30: 486357978 | H30: =IF(Table2[[#This Row],[Kontraktor]]="", "Tidak Diketahui",Table2[[#This Row],[Kontraktor]]) -> Tidak Diketahui | I30: =Table245[[#This Row],[Tanggal_Selesai]]-Table245[[#This Row],[Tanggal_Mulai]] -> 47 | J30: =Table245[[#This Row],[Anggaran]]/Table245[[#This Row],[Durasi_Proyek]] -> 10348042 | K30: =YEAR(Table245[[#This Row],[Tanggal_Mulai]]) -> 2023
A31: CN-0015-2024 | B31: =IF(Table2[[#This Row],[Jenis_Proyek]]="", "Tidak Diketahui", Table2[[#This Row],[Jenis_Proyek]]) -> Jalan Raya | C31: =IF(Table2[[#This Row],[Lokasi]]="", "Tidak Diketahui", Table2[[#This Row],[Lokasi]]) -> Surabaya | D31: =IF(Table2[[#This Row],[Nama_Proyek]]="", "Tidak Diketahui", Table2[[#This Row],[Nama_Proyek]]) -> Perbaikan Jalan Raya Surabaya | E31: 45340 | F31: 45371 | G31: 810414368 | H31: =IF(Table2[[#This Row],[Kontraktor]]="", "Tidak Diketahui",Table2[[#This Row],[Kontraktor]]) -> PT C | I31: =Table245[[#This Row],[Tanggal_Selesai]]-Table245[[#This Row],[Tanggal_Mulai]] -> 31 | J31: =Table245[[#This Row],[Anggaran]]/Table245[[#This Row],[Durasi_Proyek]] -> 26142399 | K31: =YEAR(Table245[[#This Row],[Tanggal_Mulai]]) -> 2024
A32: CN-0016-2023 | B32: =IF(Table2[[#This Row],[Jenis_Proyek]]="", "Tidak Diketahui", Table2[[#This Row],[Jenis_Proyek]]) -> Jalan Raya | C32: =IF(Table2[[#This Row],[Lokasi]]="", "Tidak Diketahui", Table2[[#This Row],[Lokasi]]) -> Tomohon | D32: =IF(Table2[[#This Row],[Nama_Proyek]]="", "Tidak Diketahui", Table2[[#This Row],[Nama_Proyek]]) -> Perbaikan Jalan Raya Tomohon | E32: 44938 | F32: 45262 | G32: 341929482 | H32: =IF(Table2[[#This Row],[Kontraktor]]="", "Tidak Diketahui",Table2[[#This Row],[Kontraktor]]) -> PT. Yuniar Hakim Tbk | I32: =Table245[[#This Row],[Tanggal_Selesai]]-Table245[[#This Row],[Tanggal_Mulai]] -> 324 | J32: =Table245[[#This Row],[Anggaran]]/Table245[[#This Row],[Durasi_Proyek]] -> 1055337.9 | K32: =YEAR(Table245[[#This Row],[Tanggal_Mulai]]) -> 2023
A33: CN-0016-2024 | B33: =IF(Table2[[#This Row],[Jenis_Proyek]]="", "Tidak Diketahui", Table2[[#This Row],[Jenis_Proyek]]) -> Jalan Raya | C33: =IF(Table2[[#This Row],[Lokasi]]="", "Tidak Diketahui", Table2[[#This Row],[Lokasi]]) -> Bau-Bau | D33: =IF(Table2[[#This Row],[Nama_Proyek]]="", "Tidak Diketahui", Table2[[#This Row],[Nama_Proyek]]) -> Perbaikan Jalan Raya Bau-Bau | E33: 45341 | F33: 45388 | G33: 599466235 | H33: =IF(Table2[[#This Row],[Kontraktor]]="", "Tidak Diketahui",Table2[[#This Row],[Kontraktor]]) -> PT. Yuniar Hakim Tbk | I33: =Table245[[#This Row],[Tanggal_Selesai]]-Table245[[#This Row],[Tanggal_Mulai]] -> 47 | J33: =Table245[[#This Row],[Anggaran]]/Table245[[#This Row],[Durasi_Proyek]] -> 12754601 | K33: =YEAR(Table245[[#This Row],[Tanggal_Mulai]]) -> 2024
A34: CN-0017-2023 | B34: =IF(Table2[[#This Row],[Jenis_Proyek]]="", "Tidak Diketahui", Table2[[#This Row],[Jenis_Proyek]]) -> Gedung | C34: =IF(Table2[[#This Row],[Lokasi]]="", "Tidak Diketahui", Table2[[#This Row],[Lokasi]]) -> Tomohon | D34: =IF(Table2[[#This Row],[Nama_Proyek]]="", "Tidak Diketahui", Table2[[#This Row],[Nama_Proyek]]) -> Perbaikan Gedung Pemerintah Tomohon | E34: 44939 | F34: 45185 | G34: 4929333305 | H34: =IF(Table2[[#This Row],[Kontraktor]]="", "Tidak Diketahui",Table2[[#This Row],[Kontraktor]]) -> PT. Yuniar Hakim Tbk | I34: =Table245[[#This Row],[Tanggal_Selesai]]-Table245[[#This Row],[Tanggal_Mulai]] -> 246 | J34: =Table245[[#This Row],[Anggaran]]/Table245[[#This Row],[Durasi_Proyek]] -> 20037940 | K34: =YEAR(Table245[[#This Row],[Tanggal_Mulai]]) -> 2023
A35: CN-0017-2024 | B35: =IF(Table2[[#This Row],[Jenis_Proyek]]="", "Tidak Diketahui", Table2[[#This Row],[Jenis_Proyek]]) -> Drainase | C35: =IF(Table2[[#This Row],[Lokasi]]="", "Tidak Diketahui", Table2[[#This Row],[Lokasi]]) -> Bandung | D35: =IF(Table2[[#This Row],[Nama_Proyek]]="", "Tidak Diketahui", Table2[[#This Row],[Nama_Proyek]]) -> Perbaikan Drainase Bandung | E35: 45341 | F35: 45350 | G35: 333089653 | H35: =IF(Table2[[#This Row],[Kontraktor]]="", "Tidak Diketahui",Table2[[#This Row],[Kontraktor]]) -> PT B | I35: =Table245[[#This Row],[Tanggal_Selesai]]-Table245[[#This Row],[Tanggal_Mulai]] -> 9 | J35: =Table245[[#This Row],[Anggaran]]/Table245[[#This Row],[Durasi_Proyek]] -> 37009961 | K35: =YEAR(Table245[[#This Row],[Tanggal_Mulai]]) -> 2024
... A228: CN-0207-2023 | B228: =IF(Table2[[#This Row],[Jenis_Proyek]]="", "Tidak Diketahui", Table2[[#This Row],[Jenis_Proyek]]) -> Jembatan | C228: =IF(Table2[[#This Row],[Lokasi]]="", "Tidak Diketahui", Table2[[#This Row],[Lokasi]]) -> Medan | D228: =IF(Table2[[#This Row],[Nama_Proyek]]="", "Tidak Diketahui", Table2[[#This Row],[Nama_Proyek]]) -> Pembuatan Jembatan Medan | E228: 45090 | F228: 45220 | G228: 4655083177 | H228: =IF(Table2[[#This Row],[Kontraktor]]="", "Tidak Diketahui",Table2[[#This Row],[Kontraktor]]) -> PT B | I228: =Table245[[#This Row],[Tanggal_Selesai]]-Table245[[#This Row],[Tanggal_Mulai]] -> 130 | J228: =Table245[[#This Row],[Anggaran]]/Table245[[#This Row],[Durasi_Proyek]] -> 35808332 | K228: =YEAR(Table245[[#This Row],[Tanggal_Mulai]]) -> 2023
A229: CN-0208-2023 | B229: =IF(Table2[[#This Row],[Jenis_Proyek]]="", "Tidak Diketahui", Table2[[#This Row],[Jenis_Proyek]]) -> Drainase | C229: =IF(Table2[[#This Row],[Lokasi]]="", "Tidak Diketahui", Table2[[#This Row],[Lokasi]]) -> Bandung | D229: =IF(Table2[[#This Row],[Nama_Proyek]]="", "Tidak Diketahui", Table2[[#This Row],[Nama_Proyek]]) -> Perbaikan Drainase Bandung | E229: 45091 | F229: 45091 | G229: 612637613 | H229: =IF(Table2[[#This Row],[Kontraktor]]="", "Tidak Diketahui",Table2[[#This Row],[Kontraktor]]) -> PT B | I229: 1 | J229: =Table245[[#This Row],[Anggaran]]/Table245[[#This Row],[Durasi_Proyek]] -> 612637613 | K229: =YEAR(Table245[[#This Row],[Tanggal_Mulai]]) -> 2023
A230: CN-0209-2023 | B230: =IF(Table2[[#This Row],[Jenis_Proyek]]="", "Tidak Diketahui", Table2[[#This Row],[Jenis_Proyek]]) -> Jembatan | C230: =IF(Table2[[#This Row],[Lokasi]]="", "Tidak Diketahui", Table2[[#This Row],[Lokasi]]) -> Bandung | D230: =IF(Table2[[#This Row],[Nama_Proyek]]="", "Tidak Diketahui", Table2[[#This Row],[Nama_Proyek]]) -> Pembuatan Jembatan Bandung | E230: 45093 | F230: 45425 | G230: 765288058 | H230: =IF(Table2[[#This Row],[Kontraktor]]="", "Tidak Diketahui",Table2[[#This Row],[Kontraktor]]) -> CV Sihombing | I230: =Table245[[#This Row],[Tanggal_Selesai]]-Table245[[#This Row],[Tanggal_Mulai]] -> 332 | J230: =Table245[[#This Row],[Anggaran]]/Table245[[#This Row],[Durasi_Proyek]] -> 2305084.5 | K230: =YEAR(Table245[[#This Row],[Tanggal_Mulai]]) -> 2023
A231: CN-0210-2023 | B231: =IF(Table2[[#This Row],[Jenis_Proyek]]="", "Tidak Diketahui", Table2[[#This Row],[Jenis_Proyek]]) -> Jalan Raya | C231: =IF(Table2[[#This Row],[Lokasi]]="", "Tidak Diketahui", Table2[[#This Row],[Lokasi]]) -> Depok | D231: =IF(Table2[[#This Row],[Nama_Proyek]]="", "Tidak Diketahui", Table2[[#This Row],[Nama_Proyek]]) -> Perbaikan Jalan Raya Depok | E231: 45093 | F231: 45337 | G231: 996933795 | H231: =IF(Table2[[#This Row],[Kontraktor]]="", "Tidak Diketahui",Table2[[#This Row],[Kontraktor]]) -> PT D | I231: =Table245[[#This Row],[Tanggal_Selesai]]-Table245[[#This Row],[Tanggal_Mulai]] -> 244 | J231: =Table245[[#This Row],[Anggaran]]/Table245[[#This Row],[Durasi_Proyek]] -> 4085794.2 | K231: =YEAR(Table245[[#This Row],[Tanggal_Mulai]]) -> 2023
A232: CN-0211-2023 | B232: =IF(Table2[[#This Row],[Jenis_Proyek]]="", "Tidak Diketahui", Table2[[#This Row],[Jenis_Proyek]]) -> Gedung | C232: =IF(Table2[[#This Row],[Lokasi]]="", "Tidak Diketahui", Table2[[#This Row],[Lokasi]]) -> Jakarta | D232: =IF(Table2[[#This Row],[Nama_Proyek]]="", "Tidak Diketahui", Table2[[#This Row],[Nama_Proyek]]) -> Perbaikan Gedung Pemerintah Jakarta | E232: 45093 | F232: 45280 | G232: 6355661362 | H232: =IF(Table2[[#This Row],[Kontraktor]]="", "Tidak Diketahui",Table2[[#This Row],[Kontraktor]]) -> Tidak Diketahui | I232: =Table245[[#This Row],[Tanggal_Selesai]]-Table245[[#This Row],[Tanggal_Mulai]] -> 187 | J232: =Table245[[#This Row],[Anggaran]]/Table245[[#This Row],[Durasi_Proyek]] -> 33987494 | K232: =YEAR(Table245[[#This Row],[Tanggal_Mulai]]) -> 2023
A233: CN-0212-2023 | B233: =IF(Table2[[#This Row],[Jenis_Proyek]]="", "Tidak Diketahui", Table2[[#This Row],[Jenis_Proyek]]) -> Jembatan | C233: =IF(Table2[[#This Row],[Lokasi]]="", "Tidak Diketahui", Table2[[#This Row],[Lokasi]]) -> Bau-Bau | D233: =IF(Table2[[#This Row],[Nama_Proyek]]="", "Tidak Diketahui", Table2[[#This Row],[Nama_Proyek]]) -> Pembuatan Jembatan Bau-Bau | E233: 45093 | F233: 45383 | G233: 6951220052 | H233: =IF(Table2[[#This Row],[Kontraktor]]="", "Tidak Diketahui",Table2[[#This Row],[Kontraktor]]) -> CV Sihombing | I233: =Table245[[#This Row],[Tanggal_Selesai]]-Table245[[#This Row],[Tanggal_Mulai]] -> 290 | J233: =Table245[[#This Row],[Anggaran]]/Table245[[#This Row],[Durasi_Proyek]] -> 23969724 | K233: =YEAR(Table245[[#This Row],[Tanggal_Mulai]]) -> 2023
A234: CN-0213-2023 | B234: =IF(Table2[[#This Row],[Jenis_Proyek]]="", "Tidak Diketahui", Table2[[#This Row],[Jenis_Proyek]]) -> Drainase | C234: =IF(Table2[[#This Row],[Lokasi]]="", "Tidak Diketahui", Table2[[#This Row],[Lokasi]]) -> Bandung | D234: =IF(Table2[[#This Row],[Nama_Proyek]]="", "Tidak Diketahui", Table2[[#This Row],[Nama_Proyek]]) -> Perbaikan Drainase Bandung | E234: 45095 | F234: 45423 | G234: 257229348 | H234: =IF(Table2[[#This Row],[Kontraktor]]="", "Tidak Diketahui",Table2[[#This Row],[Kontraktor]]) -> Tidak Diketahui | I234: =Table245[[#This Row],[Tanggal_Selesai]]-Table245[[#This Row],[Tanggal_Mulai]] -> 328 | J234: =Table245[[#This Row],[Anggaran]]/Table245[[#This Row],[Durasi_Proyek]] -> 784235.82 | K234: =YEAR(Table245[[#This Row],[Tanggal_Mulai]]) -> 2023
A235: CN-0214-2023 | B235: =IF(Table2[[#This Row],[Jenis_Proyek]]="", "Tidak Diketahui", Table2[[#This Row],[Jenis_Proyek]]) -> Gedung | C235: =IF(Table2[[#This Row],[Lokasi]]="", "Tidak Diketahui", Table2[[#This Row],[Lokasi]]) -> Medan | D235: =IF(Table2[[#This Row],[Nama_Proyek]]="", "Tidak Diketahui", Table2[[#This Row],[Nama_Proyek]]) -> Perbaikan Gedung Pemerintah Medan | E235: 45096 | F235: 45428 | G235: 1258024298 | H235: =IF(Table2[[#This Row],[Kontraktor]]="", "Tidak Diketahui",Table2[[#This Row],[Kontraktor]]) -> PT. Lailasari Hariyah (Persero) Tbk | I235: =Table245[[#This Row],[Tanggal_Selesai]]-Table245[[#This Row],[Tanggal_Mulai]] -> 332 | J235: =Table245[[#This Row],[Anggaran]]/Table245[[#This Row],[Durasi_Proyek]] -> 3789229.8 | K235: =YEAR(Table245[[#This Row],[Tanggal_Mulai]]) -> 2023
A236: CN-0215-2023 | B236: =IF(Table2[[#This Row],[Jenis_Proyek]]="", "Tidak Diketahui", Table2[[#This Row],[Jenis_Proyek]]) -> Drainase | C236: =IF(Table2[[#This Row],[Lokasi]]="", "Tidak Diketahui", Table2[[#This Row],[Lokasi]]) -> Makassar | D236: =IF(Table2[[#This Row],[Nama_Proyek]]="", "Tidak Diketahui", Table2[[#This Row],[Nama_Proyek]]) -> Perbaikan Drainase Makassar | E236: 45096 | F236: 45199 | G236: 375761303 | H236: =IF(Table2[[#This Row],[Kontraktor]]="", "Tidak Diketahui",Table2[[#This Row],[Kontraktor]]) -> PT A | I236: =Table245[[#This Row],[Tanggal_Selesai]]-Table245[[#This Row],[Tanggal_Mulai]] -> 103 | J236: =Table245[[#This Row],[Anggaran]]/Table245[[#This Row],[Durasi_Proyek]] -> 3648168 | K236: =YEAR(Table245[[#This Row],[Tanggal_Mulai]]) -> 2023
A237: CN-0216-2023 | B237: =IF(Table2[[#This Row],[Jenis_Proyek]]="", "Tidak Diketahui", Table2[[#This Row],[Jenis_Proyek]]) -> Gedung | C237: =IF(Table2[[#This Row],[Lokasi]]="", "Tidak Diketahui", Table2[[#This Row],[Lokasi]]) -> Depok | D237: =IF(Table2[[#This Row],[Nama_Proyek]]="", "Tidak Diketahui", Table2[[#This Row],[Nama_Proyek]]) -> Perbaikan Gedung Pemerintah Depok | E237: 45097 | F237: 45129 | G237: 6540978129 | H237: =IF(Table2[[#This Row],[Kontraktor]]="", "Tidak Diketahui",Table2[[#This Row],[Kontraktor]]) -> PT D | I237: =Table245[[#This Row],[Tanggal_Selesai]]-Table245[[#This Row],[Tanggal_Mulai]] -> 32 | J237: =Table245[[#This Row],[Anggaran]]/Table245[[#This Row],[Durasi_Proyek]] -> 2.0440557e+08 | K237: =YEAR(Table245[[#This Row],[Tanggal_Mulai]]) -> 2023
A238: CN-0217-2023 | B238: =IF(Table2[[#This Row],[Jenis_Proyek]]="", "Tidak Diketahui", Table2[[#This Row],[Jenis_Proyek]]) -> Drainase | C238: =IF(Table2[[#This Row],[Lokasi]]="", "Tidak Diketahui", Table2[[#This Row],[Lokasi]]) -> Jakarta | D238: =IF(Table2[[#This Row],[Nama_Proyek]]="", "Tidak Diketahui", Table2[[#This Row],[Nama_Proyek]]) -> Perbaikan Drainase Jakarta | E238: 45098 | F238: 45142 | G238: 342017973 | H238: =IF(Table2[[#This Row],[Kontraktor]]="", "Tidak Diketahui",Table2[[#This Row],[Kontraktor]]) -> PT. Yuniar Hakim Tbk | I238: =Table245[[#This Row],[Tanggal_Selesai]]-Table245[[#This Row],[Tanggal_Mulai]] -> 44 | J238: =Table245[[#This Row],[Anggaran]]/Table245[[#This Row],[Durasi_Proyek]] -> 7773135.8 | K238: =YEAR(Table245[[#This Row],[Tanggal_Mulai]]) -> 2023
A239: CN-0218-2023 | B239: =IF(Table2[[#This Row],[Jenis_Proyek]]="", "Tidak Diketahui", Table2[[#This Row],[Jenis_Proyek]]) -> Jembatan | C239: =IF(Table2[[#This Row],[Lokasi]]="", "Tidak Diketahui", Table2[[#This Row],[Lokasi]]) -> Bau-Bau | D239: =IF(Table2[[#This Row],[Nama_Proyek]]="", "Tidak Diketahui", Table2[[#This Row],[Nama_Proyek]]) -> Perbaikan Jembatan Bau-Bau | E239: 45098 | F239: 45292 | G239: 4806164886 | H239: =IF(Table2[[#This Row],[Kontraktor]]="", "Tidak Diketahui",Table2[[#This Row],[Kontraktor]]) -> PT. Yuniar Hakim Tbk | I239: =Table245[[#This Row],[Tanggal_Selesai]]-Table245[[#This Row],[Tanggal_Mulai]] -> 194 | J239: =Table245[[#This Row],[Anggaran]]/Table245[[#This Row],[Durasi_Proyek]] -> 24774046 | K239: =YEAR(Table245[[#This Row],[Tanggal_Mulai]]) -> 2023
A240: CN-0219-2023 | B240: =IF(Table2[[#This Row],[Jenis_Proyek]]="", "Tidak Diketahui", Table2[[#This Row],[Jenis_Proyek]]) -> Gedung | C240: =IF(Table2[[#This Row],[Lokasi]]="", "Tidak Diketahui", Table2[[#This Row],[Lokasi]]) -> Bandung | D240: =IF(Table2[[#This Row],[Nama_Proyek]]="", "Tidak Diketahui", Table2[[#This Row],[Nama_Proyek]]) -> Perbaikan Gedung Pemerintah Bandung | E240: 45099 | F240: 45385 | G240: 9209856007 | H240: =IF(Table2[[#This Row],[Kontraktor]]="", "Tidak Diketahui",Table2[[#This Row],[Kontraktor]]) -> PT A | I240: =Table245[[#This Row],[Tanggal_Selesai]]-Table245[[#This Row],[Tanggal_Mulai]] -> 286 | J240: =Table245[[#This Row],[Anggaran]]/Table245[[#This Row],[Durasi_Proyek]] -> 32202294 | K240: =YEAR(Table245[[#This Row],[Tanggal_Mulai]]) -> 2023
...

Sheet Pivot Table
B2: Total Proyek | C2: Total Anggaran | E2: Jenis Proyek | F2: Rata-rata Anggaran per Proyek | H2: Jenis Proyek | I2: Rata-rata Anggaran per Hari | K2: Kontraktor | L2: Jumlah | N2: Kontraktor | O2: Total Anggaran
B3: 499 | C3: 1358476943485 | E3: Drainase | F3: 4.7362921e+08 | H3: Jalan Raya | I3: 4736147 | K3: PT D | L3: 74 | N3: PT. Lailasari Hariyah (Persero) Tbk | O3: 118121895137
E4: Jalan Raya | F4: 5.8080327e+08 | H4: Drainase | I4: 14367305 | K4: CV Sihombing | L4: 72 | N4: PT B | O4: 146967733639
