Workbook

Sheet Ori Dataset (ChatGPT)
A1: ID_Proyek | B1: Jenis_Proyek | C1: Lokasi | D1: Nama_Proyek | E1: Panjang_Jalan | F1: Tanggal_Mulai | G1: Tanggal_Selesai | H1: Durasi_Proyek | I1: Anggaran | J1: Kontraktor | K1: Sumber_Dana
A2: CN-0001-2023 | B2: Jalan Raya | C2: Tomohon | D2: Pembangunan Jalan Raya Tomohon | E2: 31.76 | F2: 45064 | G2: 45199 | H2: 135 | I2: 4887210098 | J2: Perum Lailasari Hariyah (Persero) Tbk | K2: APBN 2023
A3: CN-0002-2023 | B3: Gedung | C3: Makassar | D3: Pembangunan Gedung Pemerintah Makassar | F3: 45118 | G3: 45288 | H3: 170 | I3: 2534374084 | J3: PT A | K3: APBD 2023
A4: CN-0003-2023 | B4: Jalan Raya | C4: Depok | D4: Pembangunan Jalan Raya Depok | E4: 46.32 | F4: 45017 | G4: 45162 | H4: 145 | I4: 718301152 | J4: Perum Yuniar Hakim Tbk | K4: APBD 2023
A5: CN-0004-2023 | B5: Jalan Raya | C5: Makassar | D5: Pembangunan Jalan Raya Makassar | E5: 20.81 | F5: 45263 | G5: 45413 | H5: 150 | I5: 1402997498 | J5: PT A | K5: APBN 2023
A6: CN-0005-2023 | B6: Jembatan | C6: Bau-Bau | D6: Rehabilitasi Jembatan Bau-Bau | F6: 45063 | G6: 45233 | H6: 170 | I6: 973230661 | J6: PT C | K6: APBD 2023
A7: CN-0006-2023 | B7: Drainase | C7: Bandung | D7: Perbaikan Drainase Bandung | E7: 1.34 | F7: 44927 | G7: 44994 | H7: 67 | I7: 567100601 | J7: Perum Lailasari Hariyah (Persero) Tbk | K7: APBD 2023
A8: CN-0007-2023 | B8: Jembatan | C8: Jakarta | D8: Rehabilitasi Jembatan Jakarta | F8: 45035 | G8: 45339 | H8: 304 | I8: 4695148263 | K8: APBD 2023
A9: CN-0008-2023 | B9: Jembatan | C9: Medan | D9: Rehabilitasi Jembatan Medan | F9: 44989 | G9: 45301 | H9: 312 | I9: 1359388722 | J9: CV Sihombing | K9: APBD 2023
A10: CN-0009-2023 | B10: Jalan Raya | C10: Bandung | D10: Pembangunan Jalan Raya Bandung | E10: 37.14 | F10: 44948 | G10: 45054 | H10: 106 | I10: 4866835678 | J10: Perum Yuniar Hakim Tbk | K10: APBD 2023
A11: CN-0010-2023 | B11: Drainase | C11: Surabaya | D11: Perbaikan Drainase Surabaya | E11: 1.17 | F11: 45036 | G11: 45119 | H11: 83 | I11: 2094613916 | J11: PT D | K11: APBN 2023
A12: CN-0011-2023 | B12: Jalan Raya | C12: Depok | D12: Pembangunan Jalan Raya Depok | E12: 24.95 | F12: 45226 | G12: 45403 | H12: 177 | I12: 4695488551 | J12: PT A | K12: APBD 2023
A13: CN-0012-2023 | B13: Gedung | C13: Jakarta | D13: Pembangunan Gedung Pemerintah Jakarta | F13: 45320 | G13: 45161 | H13: -159 | I13: 1108345388 | J13: CV Sihombing | K13: APBN 2023
A14: CN-0013-2023 | B14: Drainase | C14: Bandung | D14: Perbaikan Drainase Bandung | E14: 3.51 | F14: 45338 | G14: 45128 | H14: -210 | I14: 4343883992 | J14: PT A | K14: APBN 2023
A15: CN-0014-2023 | B15: Jembatan | C15: Tomohon | D15: Rehabilitasi Jembatan Tomohon | F15: 45249 | G15: 45590 | H15: 341 | I15: 3933046847 | J15: PT A | K15: APBD 2023
A16: CN-0015-2023 | B16: Jembatan | C16: Makassar | D16: Rehabilitasi Jembatan Makassar | F16: 45179 | G16: 45400 | H16: 221 | I16: 3381767421 | J16: CV Sihombing | K16: APBD 2023
A17: CN-0016-2023 | B17: Flyover | C17: Bandung | D17: Pembangunan Flyover Bandung | F17: 45128 | G17: 45204 | H17: 76 | I17: 4180846335 | J17: PT C | K17: APBN 2023
A18: CN-0017-2023 | B18: Jalan Raya | C18: Medan | D18: Pembangunan Jalan Raya Medan | E18: 35.31 | F18: 44938 | G18: 44985 | H18: 47 | I18: 2760864114 | K18: APBN 2023
A19: CN-0018-2023 | B19: Jalan Raya | C19: Depok | D19: Pembangunan Jalan Raya Depok | E19: 13.12 | F19: 44969 | G19: 45123 | H19: 154 | I19: 2176989260 | J19: PT C | K19: APBN 2023
A20: CN-0019-2023 | B20: Flyover | C20: Surabaya | D20: Pembangunan Flyover Surabaya | F20: 44967 | G20: 45260 | H20: 293 | I20: 4508289840 | J20: PT B | K20: APBD 2023
A21: CN-0020-2023 | B21: Drainase | C21: Medan | D21: Perbaikan Drainase Medan | E21: 3.69 | F21: 44936 | G21: 45295 | H21: 359 | I21: 811513657 | J21: PT A | K21: APBN 2023
A22: CN-0021-2023 | B22: Gedung | C22: Bandung | D22: Pembangunan Gedung Pemerintah Bandung | F22: 45129 | G22: 45264 | H22: 135 | I22: 832981859 | J22: CV Sihombing | K22: APBD 2023
A23: CN-0022-2023 | B23: Gedung | C23: Jakarta | D23: Pembangunan Gedung Pemerintah Jakarta | F23: 45074 | G23: 45326 | H23: 252 | I23: 3757105268 | K23: APBN 2023
A24: CN-0023-2023 | B24: Gedung | C24: Bau-Bau | D24: Pembangunan Gedung Pemerintah Bau-Bau | F24: 45128 | G24: 45275 | H24: 147 | I24: 4790525232 | J24: CV Sihombing | K24: APBN 2023
A25: CN-0024-2023 | B25: Drainase | C25: Medan | D25: Perbaikan Drainase Medan | E25: 1.7 | F25: 45041 | G25: 45102 | H25: 61 | I25: 1383396199 | J25: PT B | K25: APBN 2023
A26: CN-0025-2023 | B26: Jembatan | C26: Medan | D26: Rehabilitasi Jembatan Medan | F26: 44974 | G26: 45082 | H26: 108 | I26: 2462450365 | J26: Perum Yuniar Hakim Tbk | K26: APBN 2023
A27: CN-0026-2023 | B27: Drainase | C27: Tomohon | D27: Perbaikan Drainase Tomohon | E27: 1.83 | F27: 45271 | G27: 45311 | H27: 40 | I27: 1414817147 | J27: CV Sihombing | K27: APBN 2023
A28: CN-0027-2023 | B28: Flyover | C28: Depok | D28: Pembangunan Flyover Depok | F28: 45160 | G28: 45415 | H28: 255 | I28: 4665481372 | K28: APBD 2023
A29: CN-0028-2023 | B29: Jembatan | C29: Jakarta | D29: Rehabilitasi Jembatan Jakarta | F29: 44945 | G29: 45037 | H29: 92 | I29: 3016693972 | J29: Perum Yuniar Hakim Tbk | K29: APBN 2023
A30: CN-0029-2023 | B30: Jalan Raya | C30: Bau-Bau | D30: Pembangunan Jalan Raya Bau-Bau | E30: 40.5 | F30: 45033 | G30: 45370 | H30: 337 | I30: 2187758490 | J30: CV Sihombing | K30: APBD 2023
A31: CN-0030-2023 | B31: Jembatan | C31: Depok | D31: Rehabilitasi Jembatan Depok | F31: 45241 | G31: 45505 | H31: 264 | I31: 1240232201 | J31: Perum Yuniar Hakim Tbk | K31: APBN 2023
A32: CN-0031-2023 | B32: Flyover | C32: Makassar | D32: Pembangunan Flyover Makassar | F32: 45118 | G32: 45256 | H32: 138 | I32: 4866732289 | J32: PT C | K32: APBD 2023
A33: CN-0032-2023 | B33: Jembatan | C33: Bau-Bau | D33: Rehabilitasi Jembatan Bau-Bau | F33: 44943 | G33: 45027 | H33: 84 | I33: 2228528699 | J33: CV Sihombing | K33: APBN 2023
A34: CN-0033-2023 | B34: Drainase | C34: Bandung | D34: Perbaikan Drainase Bandung | E34: 1.89 | F34: 45036 | G34: 45313 | H34: 277 | I34: 2685215729 | K34: APBN 2023
A35: CN-0034-2023 | B35: Drainase | C35: Bau-Bau | D35: Perbaikan Drainase Bau-Bau | E35: 1.49 | F35: 45076 | G35: 45355 | H35: 279 | I35: 1491624045 | J35: Perum Yuniar Hakim Tbk | K35: APBD 2023
A36: CN-0035-2023 | B36: Jembatan | C36: Bandung | D36: Rehabilitasi Jembatan Bandung | F36: 45240 | G36: 44995 | H36: -245 | I36: 2006686424 | J36: PT D | K36: APBN 2023
A37: CN-0036-2023 | B37: Gedung | C37: Depok | D37: Pembangunan Gedung Pemerintah Depok | F37: 45208 | G37: 45388 | H37: 180 | I37: 3436590647 | J37: PT A | K37: APBD 2023
A38: CN-0037-2023 | B38: Drainase | C38: Makassar | D38: Perbaikan Drainase Makassar | E38: 1.38 | F38: 45223 | G38: 45586 | H38: 363 | I38: 3888778874 | K38: APBN 2023
A39: CN-0038-2023 | B39: Gedung | C39: Bandung | D39: Pembangunan Gedung Pemerintah Bandung | F39: 45072 | G39: 45108 | H39: 36 | I39: 1394109768 | J39: PT B | K39: APBD 2023
A40: CN-0039-2023 | B40: Drainase | C40: Medan | D40: Perbaikan Drainase Medan | E40: 0.23 | F40: 44932 | G40: 45108 | H40: 176 | I40: 1785906562 | J40: CV Sihombing | K40: APBN 2023
...

Sheet Raw Dataset
A1: ID_Proyek | B1: Jenis_Proyek | C1: Lokasi | D1: Nama_Proyek | E1: Tanggal_Mulai | F1: Tanggal_Selesai | G1: Anggaran | H1: Kontraktor
A2: CN-0001-2023 | B2: Drainase | C2: Bandung | D2: Perbaikan Drainase Bandung | E2: 44927 | F2: 44994 | G2: 649208256 | H2: PT. Lailasari Hariyah (Persero) Tbk
A3: CN-0001-2024 | B3: Drainase | C3: Surabaya | D3: Perbaikan Drainase Surabaya | E3: 45319 | F3: 45323 | G3: 326999652 | H3: CV Sihombing
A4: CN-0002-2023 | B4: Flyover | C4: Depok | D4: Pembuatan Flyover Depok | E4: 44927 | F4: 45062 | G4: 3474309188 | H4: CV Sihombing
A5: CN-0002-2024 | B5: Gedung | C5: Jakarta | D5: Perbaikan Gedung Pemerintah Jakarta | E5: 45320 | F5: 45336 | G5: 8587951510 | H5: CV Sihombing
A6: CN-0003-2023 | B6: Jalan Raya | C6: Bandung | D6: Perbaikan Jalan Raya Bandung | E6: 44928 | F6: 45239 | G6: 191505827
A7: CN-0003-2024 | B7: Gedung | C7: Tomohon | D7: Perbaikan Gedung Pemerintah Tomohon | E7: 45323 | F7: 45343 | G7: 8016851785 | H7: PT. Yuniar Hakim Tbk
A8: CN-0004-2023 | B8: Flyover | C8: Tomohon | D8: Pembuatan Flyover Tomohon | E8: 44928 | F8: 45006 | G8: 3979021821 | H8: PT D
A9: CN-0004-2024 | B9: Gedung | C9: Jakarta | D9: Perbaikan Gedung Pemerintah Jakarta | E9: 45325 | F9: 45342 | G9: 2153093275 | H9: PT. Yuniar Hakim Tbk
A10: CN-0005-2023 | B10: Drainase | C10: Jakarta | D10: Perbaikan Drainase Jakarta | E10: 44928 | F10: 45271 | G10: 683556997 | H10: PT A
A11: CN-0005-2024 | B11: Jembatan | C11: Bau-Bau | D11: Perbaikan Jembatan Bau-Bau | E11: 45327 | F11: 45353 | G11: 4636324090 | H11: PT. Lailasari Hariyah (Persero) Tbk
A12: CN-0006-2023 | B12: Drainase | C12: Tomohon | D12: Perbaikan Drainase Tomohon | E12: 44929 | F12: 45230 | G12: 663835414 | H12: PT B
A13: CN-0006-2024 | B13: Drainase | C13: Bandung | D13: Perbaikan Drainase Bandung | E13: 45329 | F13: 45360 | G13: 698540517 | H13: PT A
A14: CN-0007-2023 | B14: Flyover | C14: Medan | D14: Pembuatan Flyover Medan | E14: 44929 | F14: 45261 | G14: 2423693734 | H14: PT D
A15: CN-0007-2024 | B15: Drainase | C15: Depok | D15: Perbaikan Drainase Depok | E15: 45330 | F15: 45337 | G15: 313131839 | H15: PT D
A16: CN-0008-2023 | B16: Jalan Raya | C16: Bandung | D16: Perbaikan Jalan Raya Bandung | E16: 44929 | F16: 45041 | G16: 281077623 | H16: PT. Yuniar Hakim Tbk
A17: CN-0008-2024 | B17: Jembatan | C17: Jakarta | D17: Pembuatan Jembatan Jakarta | E17: 45330 | F17: 45386 | G17: 921085536 | H17: PT B
A18: CN-0009-2023 | B18: Jalan Raya | C18: Jakarta | D18: Perbaikan Jalan Raya Jakarta | E18: 44930 | F18: 45182 | G18: 241214887 | H18: PT B
... A29: CN-0014-2024 | B29: Jalan Raya | C29: Surabaya | D29: Perbaikan Jalan Raya Surabaya | E29: 45339 | F29: 45379 | G29: 545662746 | H29: PT A
A30: CN-0015-2023 | B30: Jalan Raya | C30: Medan | D30: Perbaikan Jalan Raya Medan | E30: 44938 | F30: 44985 | G30: 486357978
A31: CN-0015-2024 | B31: Jalan Raya | C31: Surabaya | D31: Perbaikan Jalan Raya Surabaya | E31: 45340 | F31: 45371 | G31: 810414368 | H31: PT C
A32: CN-0016-2023 | B32: Jalan Raya | C32: Tomohon | D32: Perbaikan Jalan Raya Tomohon | E32: 44938 | F32: 45262 | G32: 341929482 | H32: PT. Yuniar Hakim Tbk
A33: CN-0016-2024 | B33: Jalan Raya | C33: Bau-Bau | D33: Perbaikan Jalan Raya Bau-Bau | E33: 45341 | F33: 45388 | G33: 599466235 | H33: PT. Yuniar Hakim Tbk
A34: CN-0017-2023 | B34: Gedung | C34: Tomohon | D34: Perbaikan Gedung Pemerintah Tomohon | E34: 44939 | F34: 45185 | G34: 4929333305 | H34: PT. Yuniar Hakim Tbk
A35: CN-0017-2024 | B35: Drainase | C35: Bandung | D35: Perbaikan Drainase Bandung | E35: 45341 | F35: 45350 | G35: 333089653 | H35: PT B
A36: CN-0018-2023 | B36: Drainase | C36: Tomohon | D36: Perbaikan Drainase Tomohon | E36: 44940 | F36: 45043 | G36: 523689841 | H36: PT D
A37: CN-0018-2024 | B37: Flyover | C37: Bandung | D37: Pembuatan Flyover Bandung | E37: 45341 | F37: 45406 | G37: 3757312666 | H37: PT B
A38: CN-0019-2023 | B38: Flyover | C38: Medan | D38: Pembuatan Flyover Medan | E38: 44940 | F38: 45206 | G38: 3894709817 | H38: PT. Yuniar Hakim Tbk
A39: CN-0019-2024 | B39: Jalan Raya | C39: Depok | D39: Perbaikan Jalan Raya Depok | E39: 45343 | F39: 45382 | G39: 462876320
A40: CN-0020-2023 | B40: Jembatan | C40: Jakarta | D40: Pembuatan Jembatan Jakarta | E40: 44941 | F40: 45188 | G40: 4532376815 | H40: PT D
A41: CN-0020-2024 | B41: Jembatan | C41: Depok | D41: Pembuatan Jembatan Depok | E41: 45346 | F41: 45398 | G41: 3821117140 | H41: PT D
A42: CN-0021-2023 | B42: Flyover | C42: Bau-Bau | D42: Perbaikan Flyover Bau-Bau | E42: 44941 | F42: 45290 | G42: 4159855566 | H42: PT C
A43: CN-0022-2023 | B43: Jembatan | C43: Bandung | D43: Perbaikan Jembatan Bandung | E43: 44941 | F43: 45095 | G43: 4492886828 | H43: PT D
A44: CN-0023-2023 | B44: Jembatan | C44: Surabaya | D44: Pembuatan Jembatan Surabaya | E44: 44942 | F44: 45034 | G44: 1424729417 | H44: PT. Yuniar Hakim Tbk
A45: CN-0024-2023 | B45: Jembatan | C45: Bau-Bau | D45: Pembuatan Jembatan Bau-Bau | E45: 44943 | F45: 45027 | G45: 1425616276 | H45: CV Sihombing
A46: CN-0025-2023 | B46: Jalan Raya | C46: Bandung | D46: Perbaikan Jalan Raya Bandung | E46: 44943 | F46: 45136 | G46: 307413755 | H46: CV Sihombing
A47: CN-0026-2023 | B47: Jembatan | C47: Bau-Bau | D47: Pembuatan Jembatan Bau-Bau | E47: 44944 | F47: 45113 | G47: 6929733135 | H47: PT C
A48: CN-0027-2023 | B48: Jembatan | C48: Bau-Bau | D48: Perbaikan Jembatan Bau-Bau | E48: 44944 | F48: 45284 | G48: 1567712170 | H48: PT. Yuniar Hakim Tbk
A49: CN-0028-2023 | B49: Jembatan | C49: Jakarta | D49: Pembuatan Jembatan Jakarta | E49: 44945 | F49: 45037 | G49: 3020860458 | H49: PT. Yuniar Hakim Tbk
A50: CN-0029-2023 | B50: Drainase | C50: Medan | D50: Perbaikan Drainase Medan | E50: 44946 | F50: 45105 | G50: 443234047 | H50: PT. Lailasari Hariyah (Persero) Tbk
...

Sheet Project Reference
A1: ID_Proyek
A2: CN-0001-2023
A3: CN-0001-2024
A4: CN-0002-2023
A5: CN-0002-2024
A6: CN-0003-2023
A7: CN-0003-2024
A8: CN-0004-2023
A9: CN-0004-2024
A10: CN-0005-2023
A11: CN-0005-2024
A12: CN-0006-2023
... A500: CN-0479-2023

Sheet Remove Duplicates
A1: ID_Proyek
A2: CN-0001-2023
A3: CN-0001-2024
A4: CN-0002-2023
A5: CN-0002-2024
A6: CN-0003-2023
A7: CN-0003-2024
A8: CN-0004-2023
A9: CN-0004-2024
A10: CN-0005-2023
A11: CN-0005-2024
A12: CN-0006-2023
... A501: CN-9999-2024

Sheet Variable Check List
A1: Indikator | B1: ID_Proyek | C1: Jenis_Proyek | D1: Lokasi | E1: Nama_Proyek | F1: Tanggal_Mulai | G1: Tanggal_Selesai | H1: Anggaran | I1: Kontraktor
A2: Completeness (CPT) | B2: TRUE | C2: TRUE | D2: TRUE | E2: TRUE | F2: TRUE | G2: TRUE | H2: TRUE | I2: TRUE
A3: Uniqueness (UNQ) | B3: TRUE | C3: FALSE | D3: FALSE | E3: FALSE | F3: FALSE | G3: FALSE | H3: FALSE | I3: FALSE
A4: Validity (VLD) | B4: TRUE | C4: FALSE | D4: FALSE | E4: FALSE | F4: FALSE | G4: FALSE | H4: FALSE | I4: FALSE
A5: Consistency (CNS) | B5: FALSE | C5: FALSE | D5: FALSE | E5: TRUE | F5: FALSE | G5: FALSE | H5: FALSE | I5: FALSE
A6: Feasibility (FSB) | B6: FALSE | C6: FALSE | D6: FALSE | E6: FALSE | F6: TRUE | G6: TRUE | H6: TRUE | I6: FALSE

Sheet Pivot Table
F5: CPT_ID_Proyek | G5: CPT_Jenis_Proyek | H5: CPT_Lokasi | I5: CPT_Nama_Proyek | J5: CPT_Tanggal_Mulai | K5: CPT_Tanggal_Selesai | L5: CPT_Anggaran | M5: CPT_Kontraktor | N5: UNQ_ID_Proyek | O5: VLD_ID_Proyek | P5: CNS_Nama_Proyek | Q5: FSB_Tanggal_Mulai | R5: FSB_Tanggal_Selesai | S5: FSB_Anggaran
F6: =F2/500 -> 1 | G6: =G2/500 -> 0.994 | H6: =H2/500 -> 0.996 | I6: =I2/500 -> 0.994 | J6: =J2/500 -> 1 | K6: =K2/500 -> 1 | L6: =L2/500 -> 1 | M6: =M2/500 -> 0.876 | ... S6: =S2/500 -> 0.996

Sheet Descriptive Stats
A1: Suggested Pivot Chart

Sheet Data Quality
A1: ID_Proyek | B1: Jenis_Proyek | C1: Lokasi | D1: Nama_Proyek | E1: Tanggal_Mulai | F1: Tanggal_Selesai | G1: Anggaran | H1: Kontraktor | I1: CPT_ID_Proyek | J1: CPT_Jenis_Proyek | K1: CPT_Lokasi | L1: CPT_Nama_Proyek | M1: CPT_Tanggal_Mulai | N1: CPT_Tanggal_Selesai | O1: CPT_Anggaran | P1: CPT_Kontraktor | Q1: UNQ_ID_Proyek | R1: VLD_ID_Proyek | S1: CNS_Nama_Proyek | T1: FSB_Tanggal_Mulai | U1: FSB_Tanggal_Selesai | V1: FSB_Anggaran
A2: CN-0164-2023 | B2: Gedung | C2: Makassar | D2: Perbaikan Gedung Pemerintah Makassar | E2: 45056 | F2: 45210 | G2: 22993543140 | H2: PT A | I2: =IF(ISBLANK(A2)=TRUE,0,1) -> 1 | J2: =IF(ISBLANK(B2)=TRUE,0,1) -> 1 | K2: =IF(ISBLANK(C2)=TRUE,0,1) -> 1 | L2: =IF(ISBLANK(D2)=TRUE,0,1) -> 1 | M2: =IF(ISBLANK(E2)=TRUE,0,1) -> 1 | N2: =IF(ISBLANK(F2)=TRUE,0,1) -> 1 | O2: =IF(ISBLANK(G2)=TRUE,0,1) -> 1 | P2: =IF(ISBLANK(H2)=TRUE,0,1) -> 1 | Q2: =IF(COUNTIF(A:A, A2) > 1, 0, 1) -> 1 | R2: =IF(ISERROR(VLOOKUP(A2, 'Project Reference'!A:A, 1, FALSE)), 0, 1) -> 1 | S2: =IFERROR(__xludf.DUMMYFUNCTION("IF(AND(REGEXMATCH(D2, B2), REGEXMATCH(D2, C2)), 1, 0)"),1.0) -> 1 | T2: =IF(AND(YEAR(E2)>=2023, YEAR(E2)<=2024), 1, 0) -> 1 | U2: =IF(F2-E2>=3, 1, 0) -> 1 | V2: =IF(G2>10000000000, 0, 1) -> 0
A3: CN-0200-2023 | B3: Flyover | C3: Bau-Bau | D3: Perbaikan Flyover Bau-Bau | E3: 45081 | F3: 45386 | G3: 10119728525 | H3: PT B | I3: =IF(ISBLANK(A3)=TRUE,0,1) -> 1 | J3: =IF(ISBLANK(B3)=TRUE,0,1) -> 1 | K3: =IF(ISBLANK(C3)=TRUE,0,1) -> 1 | L3: =IF(ISBLANK(D3)=TRUE,0,1) -> 1 | M3: =IF(ISBLANK(E3)=TRUE,0,1) -> 1 | N3: =IF(ISBLANK(F3)=TRUE,0,1) -> 1 | O3: =IF(ISBLANK(G3)=TRUE,0,1) -> 1 | P3: =IF(ISBLANK(H3)=TRUE,0,1) -> 1 | Q3: =IF(COUNTIF(A:A, A3) > 1, 0, 1) -> 1 | R3: =IF(ISERROR(VLOOKUP(A3, 'Project Reference'!A:A, 1, FALSE)), 0, 1) -> 1 | S3: =IFERROR(__xludf.DUMMYFUNCTION("IF(AND(REGEXMATCH(D3, B3), REGEXMATCH(D3, C3)), 1, 0)"),1.0) -> 1 | T3: =IF(AND(YEAR(E3)>=2023, YEAR(E3)<=2024), 1, 0) -> 1 | U3: =IF(F3-E3>=3, 1, 0) -> 1 | V3: =IF(G3>10000000000, 0, 1) -> 0
A4: CN-9999-2024 | B4: Jalan Raya | C4: Jakarta | D4: Tes | E4: 45292 | F4: 45292 | G4: 105133426 | H4: x | I4: =IF(ISBLANK(A4)=TRUE,0,1) -> 1 | J4: =IF(ISBLANK(B4)=TRUE,0,1) -> 1 | K4: =IF(ISBLANK(C4)=TRUE,0,1) -> 1 | L4: =IF(ISBLANK(D4)=TRUE,0,1) -> 1 | M4: =IF(ISBLANK(E4)=TRUE,0,1) -> 1 | N4: =IF(ISBLANK(F4)=TRUE,0,1) -> 1 | O4: =IF(ISBLANK(G4)=TRUE,0,1) -> 1 | P4: =IF(ISBLANK(H4)=TRUE,0,1) -> 1 | Q4: =IF(COUNTIF(A:A, A4) > 1, 0, 1) -> 1 | R4: =IF(ISERROR(VLOOKUP(A4, 'Project Reference'!A:A, 1, FALSE)), 0, 1) -> 0 | S4: =IFERROR(__xludf.DUMMYFUNCTION("IF(AND(REGEXMATCH(D4, B4), REGEXMATCH(D4, C4)), 1, 0)"),0.0) -> 0 | T4: =IF(AND(YEAR(E4)>=2023, YEAR(E4)<=2024), 1, 0) -> 1 | U4: =IF(F4-E4>=3, 1, 0) -> 0 | V4: =IF(G4>10000000000, 0, 1) -> 1
A5: CN-0192-2023 | B5: Gedung | C5: Surabaya | D5: Perbaikan Gedung Pemerintah Surabaya | E5: 45078 | F5: 45153 | G5: 1206249778 | H5: PT B | I5: =IF(ISBLANK(A5)=TRUE,0,1) -> 1 | J5: =IF(ISBLANK(B5)=TRUE,0,1) -> 1 | K5: =IF(ISBLANK(C5)=TRUE,0,1) -> 1 | L5: =IF(ISBLANK(D5)=TRUE,0,1) -> 1 | M5: =IF(ISBLANK(E5)=TRUE,0,1) -> 1 | N5: =IF(ISBLANK(F5)=TRUE,0,1) -> 1 | O5: =IF(ISBLANK(G5)=TRUE,0,1) -> 1 | P5: =IF(ISBLANK(H5)=TRUE,0,1) -> 1 | Q5: =IF(COUNTIF(A:A, A5) > 1, 0, 1) -> 0 | R5: =IF(ISERROR(VLOOKUP(A5, 'Project Reference'!A:A, 1, FALSE)), 0, 1) -> 1 | S5: =IFERROR(__xludf.DUMMYFUNCTION("IF(AND(REGEXMATCH(D5, B5), REGEXMATCH(D5, C5)), 1, 0)"),1.0) -> 1 | T5: =IF(AND(YEAR(E5)>=2023, YEAR(E5)<=2024), 1, 0) -> 1 | U5: =IF(F5-E5>=3, 1, 0) -> 1 | V5: =IF(G5>10000000000, 0, 1) -> 1
A6: CN-0192-2023 | B6: Gedung | C6: Surabaya | D6: Perbaikan Gedung Pemerintah Surabaya | E6: 45078 | F6: 45153 | G6: 6060807570 | H6: PT. Yuniar Hakim Tbk | I6: =IF(ISBLANK(A6)=TRUE,0,1) -> 1 | J6: =IF(ISBLANK(B6)=TRUE,0,1) -> 1 | K6: =IF(ISBLANK(C6)=TRUE,0,1) -> 1 | L6: =IF(ISBLANK(D6)=TRUE,0,1) -> 1 | M6: =IF(ISBLANK(E6)=TRUE,0,1) -> 1 | N6: =IF(ISBLANK(F6)=TRUE,0,1) -> 1 | O6: =IF(ISBLANK(G6)=TRUE,0,1) -> 1 | P6: =IF(ISBLANK(H6)=TRUE,0,1) -> 1 | Q6: =IF(COUNTIF(A:A, A6) > 1, 0, 1) -> 0 | R6: =IF(ISERROR(VLOOKUP(A6, 'Project Reference'!A:A, 1, FALSE)), 0, 1) -> 1 | S6: =IFERROR(__xludf.DUMMYFUNCTION("IF(AND(REGEXMATCH(D6, B6), REGEXMATCH(D6, C6)), 1, 0)"),1.0) -> 1 | T6: =IF(AND(YEAR(E6)>=2023, YEAR(E6)<=2024), 1, 0) -> 1 | U6: =IF(F6-E6>=3, 1, 0) -> 1 | V6: =IF(G6>10000000000, 0, 1) -> 1
A7: CN-0188-2023 | D7: Perbaikan Gedung Pemerintah Surabaya | E7: 45074 | F7: 45243 | G7: 8372699981 | I7: =IF(ISBLANK(A7)=TRUE,0,1) -> 1 | J7: =IF(ISBLANK(B7)=TRUE,0,1) -> 0 | K7: =IF(ISBLANK(C7)=TRUE,0,1) -> 0 | L7: =IF(ISBLANK(D7)=TRUE,0,1) -> 1 | M7: =IF(ISBLANK(E7)=TRUE,0,1) -> 1 | N7: =IF(ISBLANK(F7)=TRUE,0,1) -> 1 | O7: =IF(ISBLANK(G7)=TRUE,0,1) -> 1 | P7: =IF(ISBLANK(H7)=TRUE,0,1) -> 0 | Q7: =IF(COUNTIF(A:A, A7) > 1, 0, 1) -> 1 | R7: =IF(ISERROR(VLOOKUP(A7, 'Project Reference'!A:A, 1, FALSE)), 0, 1) -> 1 | S7: =IFERROR(__xludf.DUMMYFUNCTION("IF(AND(REGEXMATCH(D7, B7), REGEXMATCH(D7, C7)), 1, 0)"),1.0) -> 1 | T7: =IF(AND(YEAR(E7)>=2023, YEAR(E7)<=2024), 1, 0) -> 1 | U7: =IF(F7-E7>=3, 1, 0) -> 1 | V7: =IF(G7>10000000000, 0, 1) -> 1
A8: CN-0108-2023 | C8: Bandung | E8: 45010 | F8: 45091 | G8: 2960912774 | I8: =IF(ISBLANK(A8)=TRUE,0,1) -> 1 | J8: =IF(ISBLANK(B8)=TRUE,0,1) -> 0 | K8: =IF(ISBLANK(C8)=TRUE,0,1) -> 1 | L8: =IF(ISBLANK(D8)=TRUE,0,1) -> 0 | M8: =IF(ISBLANK(E8)=TRUE,0,1) -> 1 | N8: =IF(ISBLANK(F8)=TRUE,0,1) -> 1 | O8: =IF(ISBLANK(G8)=TRUE,0,1) -> 1 | P8: =IF(ISBLANK(H8)=TRUE,0,1) -> 0 | Q8: =IF(COUNTIF(A:A, A8) > 1, 0, 1) -> 1 | R8: =IF(ISERROR(VLOOKUP(A8, 'Project Reference'!A:A, 1, FALSE)), 0, 1) -> 1 | S8: =IFERROR(__xludf.DUMMYFUNCTION("IF(AND(REGEXMATCH(D8, B8), REGEXMATCH(D8, C8)), 1, 0)"),0.0) -> 0 | T8: =IF(AND(YEAR(E8)>=2023, YEAR(E8)<=2024), 1, 0) -> 1 | U8: =IF(F8-E8>=3, 1, 0) -> 1 | V8: =IF(G8>10000000000, 0, 1) -> 1
A9: CN-0058-2023 | E9: 44969 | F9: 45030 | G9: 314690070 | H9: CV Sihombing | I9: =IF(ISBLANK(A9)=TRUE,0,1) -> 1 | J9: =IF(ISBLANK(B9)=TRUE,0,1) -> 0 | K9: =IF(ISBLANK(C9)=TRUE,0,1) -> 0 | L9: =IF(ISBLANK(D9)=TRUE,0,1) -> 0 | M9: =IF(ISBLANK(E9)=TRUE,0,1) -> 1 | N9: =IF(ISBLANK(F9)=TRUE,0,1) -> 1 | O9: =IF(ISBLANK(G9)=TRUE,0,1) -> 1 | P9: =IF(ISBLANK(H9)=TRUE,0,1) -> 1 | Q9: =IF(COUNTIF(A:A, A9) > 1, 0, 1) -> 1 | R9: =IF(ISERROR(VLOOKUP(A9, 'Project Reference'!A:A, 1, FALSE)), 0, 1) -> 1 | S9: =IFERROR(__xludf.DUMMYFUNCTION("IF(AND(REGEXMATCH(D9, B9), REGEXMATCH(D9, C9)), 1, 0)"),1.0) -> 1 | T9: =IF(AND(YEAR(E9)>=2023, YEAR(E9)<=2024), 1, 0) -> 1 | U9: =IF(F9-E9>=3, 1, 0) -> 1 | V9: =IF(G9>10000000000, 0, 1) -> 1
A10: CN-0003-2023 | B10: Jalan Raya | C10: Bandung | D10: Perbaikan Jalan Raya Bandung | E10: 44928 | F10: 45239 | G10: 191505827 | I10: =IF(ISBLANK(A10)=TRUE,0,1) -> 1 | J10: =IF(ISBLANK(B10)=TRUE,0,1) -> 1 | K10: =IF(ISBLANK(C10)=TRUE,0,1) -> 1 | L10: =IF(ISBLANK(D10)=TRUE,0,1) -> 1 | M10: =IF(ISBLANK(E10)=TRUE,0,1) -> 1 | N10: =IF(ISBLANK(F10)=TRUE,0,1) -> 1 | O10: =IF(ISBLANK(G10)=TRUE,0,1) -> 1 | P10: =IF(ISBLANK(H10)=TRUE,0,1) -> 0 | Q10: =IF(COUNTIF(A:A, A10) > 1, 0, 1) -> 1 | R10: =IF(ISERROR(VLOOKUP(A10, 'Project Reference'!A:A, 1, FALSE)), 0, 1) -> 1 | S10: =IFERROR(__xludf.DUMMYFUNCTION("IF(AND(REGEXMATCH(D10, B10), REGEXMATCH(D10, C10)), 1, 0)"),1.0) -> 1 | T10: =IF(AND(YEAR(E10)>=2023, YEAR(E10)<=2024), 1, 0) -> 1 | U10: =IF(F10-E10>=3, 1, 0) -> 1 | V10: =IF(G10>10000000000, 0, 1) -> 1
A11: CN-0015-2023 | B11: Jalan Raya | C11: Medan | D11: Perbaikan Jalan Raya Medan | E11: 44938 | F11: 44985 | G11: 486357978 | I11: =IF(ISBLANK(A11)=TRUE,0,1) -> 1 | J11: =IF(ISBLANK(B11)=TRUE,0,1) -> 1 | K11: =IF(ISBLANK(C11)=TRUE,0,1) -> 1 | L11: =IF(ISBLANK(D11)=TRUE,0,1) -> 1 | M11: =IF(ISBLANK(E11)=TRUE,0,1) -> 1 | N11: =IF(ISBLANK(F11)=TRUE,0,1) -> 1 | O11: =IF(ISBLANK(G11)=TRUE,0,1) -> 1 | P11: =IF(ISBLANK(H11)=TRUE,0,1) -> 0 | Q11: =IF(COUNTIF(A:A, A11) > 1, 0, 1) -> 1 | R11: =IF(ISERROR(VLOOKUP(A11, 'Project Reference'!A:A, 1, FALSE)), 0, 1) -> 1 | S11: =IFERROR(__xludf.DUMMYFUNCTION("IF(AND(REGEXMATCH(D11, B11), REGEXMATCH(D11, C11)), 1, 0)"),1.0) -> 1 | T11: =IF(AND(YEAR(E11)>=2023, YEAR(E11)<=2024), 1, 0) -> 1 | U11: =IF(F11-E11>=3, 1, 0) -> 1 | V11: =IF(G11>10000000000, 0, 1) -> 1
A12: CN-0019-2024 | B12: Jalan Raya | C12: Depok | D12: Perbaikan Jalan Raya Depok | E12: 45343 | F12: 45382 | G12: 462876320 | I12: =IF(ISBLANK(A12)=TRUE,0,1) -> 1 | J12: =IF(ISBLANK(B12)=TRUE,0,1) -> 1 | K12: =IF(ISBLANK(C12)=TRUE,0,1) -> 1 | L12: =IF(ISBLANK(D12)=TRUE,0,1) -> 1 | M12: =IF(ISBLANK(E12)=TRUE,0,1) -> 1 | N12: =IF(ISBLANK(F12)=TRUE,0,1) -> 1 | O12: =IF(ISBLANK(G12)=TRUE,0,1) -> 1 | P12: =IF(ISBLANK(H12)=TRUE,0,1) -> 0 | Q12: =IF(COUNTIF(A:A, A12) > 1, 0, 1) -> 1 | R12: =IF(ISERROR(VLOOKUP(A12, 'Project Reference'!A:A, 1, FALSE)), 0, 1) -> 1 | S12: =IFERROR(__xludf.DUMMYFUNCTION("IF(AND(REGEXMATCH(D12, B12), REGEXMATCH(D12, C12)), 1, 0)"),1.0) -> 1 | T12: =IF(AND(YEAR(E12)>=2023, YEAR(E12)<=2024), 1, 0) -> 1 | U12: =IF(F12-E12>=3, 1, 0) -> 1 | V12: =IF(G12>10000000000, 0, 1) -> 1
A13: CN-0038-2023 | B13: Drainase | C13: Tomohon | D13: Perbaikan Drainase Tomohon | E13: 44954 | F13: 45186 | G13: 382266210 | I13: =IF(ISBLANK(A13)=TRUE,0,1) -> 1 | J13: =IF(ISBLANK(B13)=TRUE,0,1) -> 1 | K13: =IF(ISBLANK(C13)=TRUE,0,1) -> 1 | L13: =IF(ISBLANK(D13)=TRUE,0,1) -> 1 | M13: =IF(ISBLANK(E13)=TRUE,0,1) -> 1 | N13: =IF(ISBLANK(F13)=TRUE,0,1) -> 1 | O13: =IF(ISBLANK(G13)=TRUE,0,1) -> 1 | P13: =IF(ISBLANK(H13)=TRUE,0,1) -> 0 | Q13: =IF(COUNTIF(A:A, A13) > 1, 0, 1) -> 1 | R13: =IF(ISERROR(VLOOKUP(A13, 'Project Reference'!A:A, 1, FALSE)), 0, 1) -> 1 | S13: =IFERROR(__xludf.DUMMYFUNCTION("IF(AND(REGEXMATCH(D13, B13), REGEXMATCH(D13, C13)), 1, 0)"),1.0) -> 1 | T13: =IF(AND(YEAR(E13)>=2023, YEAR(E13)<=2024), 1, 0) -> 1 | U13: =IF(F13-E13>=3, 1, 0) -> 1 | V13: =IF(G13>10000000000, 0, 1) -> 1
A14: CN-0041-2023 | B14: Jembatan | C14: Bau-Bau | D14: Perbaikan Jembatan Bau-Bau | E14: 44955 | F14: 45116 | G14: 3703277131 | I14: =IF(ISBLANK(A14)=TRUE,0,1) -> 1 | J14: =IF(ISBLANK(B14)=TRUE,0,1) -> 1 | K14: =IF(ISBLANK(C14)=TRUE,0,1) -> 1 | L14: =IF(ISBLANK(D14)=TRUE,0,1) -> 1 | M14: =IF(ISBLANK(E14)=TRUE,0,1) -> 1 | N14: =IF(ISBLANK(F14)=TRUE,0,1) -> 1 | O14: =IF(ISBLANK(G14)=TRUE,0,1) -> 1 | P14: =IF(ISBLANK(H14)=TRUE,0,1) -> 0 | Q14: =IF(COUNTIF(A:A, A14) > 1, 0, 1) -> 1 | R14: =IF(ISERROR(VLOOKUP(A14, 'Project Reference'!A:A, 1, FALSE)), 0, 1) -> 1 | S14: =IFERROR(__xludf.DUMMYFUNCTION("IF(AND(REGEXMATCH(D14, B14), REGEXMATCH(D14, C14)), 1, 0)"),1.0) -> 1 | T14: =IF(AND(YEAR(E14)>=2023, YEAR(E14)<=2024), 1, 0) -> 1 | U14: =IF(F14-E14>=3, 1, 0) -> 1 | V14: =IF(G14>10000000000, 0, 1) -> 1
A15: CN-0045-2023 | B15: Jembatan | C15: Makassar | D15: Pembuatan Jembatan Makassar | E15: 44959 | F15: 45167 | G15: 5835541492 | I15: =IF(ISBLANK(A15)=TRUE,0,1) -> 1 | J15: =IF(ISBLANK(B15)=TRUE,0,1) -> 1 | K15: =IF(ISBLANK(C15)=TRUE,0,1) -> 1 | L15: =IF(ISBLANK(D15)=TRUE,0,1) -> 1 | M15: =IF(ISBLANK(E15)=TRUE,0,1) -> 1 | N15: =IF(ISBLANK(F15)=TRUE,0,1) -> 1 | O15: =IF(ISBLANK(G15)=TRUE,0,1) -> 1 | P15: =IF(ISBLANK(H15)=TRUE,0,1) -> 0 | Q15: =IF(COUNTIF(A:A, A15) > 1, 0, 1) -> 1 | R15: =IF(ISERROR(VLOOKUP(A15, 'Project Reference'!A:A, 1, FALSE)), 0, 1) -> 1 | S15: =IFERROR(__xludf.DUMMYFUNCTION("IF(AND(REGEXMATCH(D15, B15), REGEXMATCH(D15, C15)), 1, 0)"),1.0) -> 1 | T15: =IF(AND(YEAR(E15)>=2023, YEAR(E15)<=2024), 1, 0) -> 1 | U15: =IF(F15-E15>=3, 1, 0) -> 1 | V15: =IF(G15>10000000000, 0, 1) -> 1
A16: CN-0067-2023 | B16: Flyover | C16: Medan | D16: Perbaikan Flyover Medan | E16: 44975 | F16: 45256 | G16: 3367495384 | I16: =IF(ISBLANK(A16)=TRUE,0,1) -> 1 | J16: =IF(ISBLANK(B16)=TRUE,0,1) -> 1 | K16: =IF(ISBLANK(C16)=TRUE,0,1) -> 1 | L16: =IF(ISBLANK(D16)=TRUE,0,1) -> 1 | M16: =IF(ISBLANK(E16)=TRUE,0,1) -> 1 | N16: =IF(ISBLANK(F16)=TRUE,0,1) -> 1 | O16: =IF(ISBLANK(G16)=TRUE,0,1) -> 1 | P16: =IF(ISBLANK(H16)=TRUE,0,1) -> 0 | Q16: =IF(COUNTIF(A:A, A16) > 1, 0, 1) -> 1 | R16: =IF(ISERROR(VLOOKUP(A16, 'Project Reference'!A:A, 1, FALSE)), 0, 1) -> 1 | S16: =IFERROR(__xludf.DUMMYFUNCTION("IF(AND(REGEXMATCH(D16, B16), REGEXMATCH(D16, C16)), 1, 0)"),1.0) -> 1 | T16: =IF(AND(YEAR(E16)>=2023, YEAR(E16)<=2024), 1, 0) -> 1 | U16: =IF(F16-E16>=3, 1, 0) -> 1 | V16: =IF(G16>10000000000, 0, 1) -> 1
A17: CN-0070-2023 | B17: Gedung | C17: Jakarta | E17: 44977 | F17: 45285 | G17: 7432359735 | I17: =IF(ISBLANK(A17)=TRUE,0,1) -> 1 | J17: =IF(ISBLANK(B17)=TRUE,0,1) -> 1 | K17: =IF(ISBLANK(C17)=TRUE,0,1) -> 1 | L17: =IF(ISBLANK(D17)=TRUE,0,1) -> 0 | M17: =IF(ISBLANK(E17)=TRUE,0,1) -> 1 | N17: =IF(ISBLANK(F17)=TRUE,0,1) -> 1 | O17: =IF(ISBLANK(G17)=TRUE,0,1) -> 1 | P17: =IF(ISBLANK(H17)=TRUE,0,1) -> 0 | Q17: =IF(COUNTIF(A:A, A17) > 1, 0, 1) -> 1 | R17: =IF(ISERROR(VLOOKUP(A17, 'Project Reference'!A:A, 1, FALSE)), 0, 1) -> 1 | S17: =IFERROR(__xludf.DUMMYFUNCTION("IF(AND(REGEXMATCH(D17, B17), REGEXMATCH(D17, C17)), 1, 0)"),0.0) -> 0 | T17: =IF(AND(YEAR(E17)>=2023, YEAR(E17)<=2024), 1, 0) -> 1 | U17: =IF(F17-E17>=3, 1, 0) -> 1 | V17: =IF(G17>10000000000, 0, 1) -> 1
A18: CN-0071-2023 | B18: Gedung | C18: Surabaya | D18: Perbaikan Gedung Pemerintah Surabaya | E18: 44977 | F18: 45233 | G18: 7645065116 | I18: =IF(ISBLANK(A18)=TRUE,0,1) -> 1 | J18: =IF(ISBLANK(B18)=TRUE,0,1) -> 1 | K18: =IF(ISBLANK(C18)=TRUE,0,1) -> 1 | L18: =IF(ISBLANK(D18)=TRUE,0,1) -> 1 | M18: =IF(ISBLANK(E18)=TRUE,0,1) -> 1 | N18: =IF(ISBLANK(F18)=TRUE,0,1) -> 1 | O18: =IF(ISBLANK(G18)=TRUE,0,1) -> 1 | P18: =IF(ISBLANK(H18)=TRUE,0,1) -> 0 | Q18: =IF(COUNTIF(A:A, A18) > 1, 0, 1) -> 1 | R18: =IF(ISERROR(VLOOKUP(A18, 'Project Reference'!A:A, 1, FALSE)), 0, 1) -> 1 | S18: =IFERROR(__xludf.DUMMYFUNCTION("IF(AND(REGEXMATCH(D18, B18), REGEXMATCH(D18, C18)), 1, 0)"),1.0) -> 1 | T18: =IF(AND(YEAR(E18)>=2023, YEAR(E18)<=2024), 1, 0) -> 1 | U18: =IF(F18-E18>=3, 1, 0) -> 1 | V18: =IF(G18>10000000000, 0, 1) -> 1
A19: CN-0095-2023 | B19: Gedung | C19: Makassar | D19: Perbaikan Gedung Pemerintah Makassar | E19: 44998 | F19: 45341 | G19: 9404668499 | I19: =IF(ISBLANK(A19)=TRUE,0,1) -> 1 | J19: =IF(ISBLANK(B19)=TRUE,0,1) -> 1 | K19: =IF(ISBLANK(C19)=TRUE,0,1) -> 1 | L19: =IF(ISBLANK(D19)=TRUE,0,1) -> 1 | M19: =IF(ISBLANK(E19)=TRUE,0,1) -> 1 | N19: =IF(ISBLANK(F19)=TRUE,0,1) -> 1 | O19: =IF(ISBLANK(G19)=TRUE,0,1) -> 1 | P19: =IF(ISBLANK(H19)=TRUE,0,1) -> 0 | Q19: =IF(COUNTIF(A:A, A19) > 1, 0, 1) -> 1 | R19: =IF(ISERROR(VLOOKUP(A19, 'Project Reference'!A:A, 1, FALSE)), 0, 1) -> 1 | S19: =IFERROR(__xludf.DUMMYFUNCTION("IF(AND(REGEXMATCH(D19, B19), REGEXMATCH(D19, C19)), 1, 0)"),1.0) -> 1 | T19: =IF(AND(YEAR(E19)>=2023, YEAR(E19)<=2024), 1, 0) -> 1 | U19: =IF(F19-E19>=3, 1, 0) -> 1 | V19: =IF(G19>10000000000, 0, 1) -> 1
A20: CN-0102-2023 | B20: Jembatan | C20: Medan | D20: Perbaikan Jembatan Medan | E20: 45006 | F20: 45234 | G20: 7494641055 | I20: =IF(ISBLANK(A20)=TRUE,0,1) -> 1 | J20: =IF(ISBLANK(B20)=TRUE,0,1) -> 1 | K20: =IF(ISBLANK(C20)=TRUE,0,1) -> 1 | L20: =IF(ISBLANK(D20)=TRUE,0,1) -> 1 | M20: =IF(ISBLANK(E20)=TRUE,0,1) -> 1 | N20: =IF(ISBLANK(F20)=TRUE,0,1) -> 1 | O20: =IF(ISBLANK(G20)=TRUE,0,1) -> 1 | P20: =IF(ISBLANK(H20)=TRUE,0,1) -> 0 | Q20: =IF(COUNTIF(A:A, A20) > 1, 0, 1) -> 1 | R20: =IF(ISERROR(VLOOKUP(A20, 'Project Reference'!A:A, 1, FALSE)), 0, 1) -> 1 | S20: =IFERROR(__xludf.DUMMYFUNCTION("IF(AND(REGEXMATCH(D20, B20), REGEXMATCH(D20, C20)), 1, 0)"),1.0) -> 1 | T20: =IF(AND(YEAR(E20)>=2023, YEAR(E20)<=2024), 1, 0) -> 1 | U20: =IF(F20-E20>=3, 1, 0) -> 1 | V20: =IF(G20>10000000000, 0, 1) -> 1
A21: CN-0109-2023 | B21: Drainase | C21: Makassar | D21: Perbaikan Drainase Makassar | E21: 45011 | F21: 45235 | G21: 421859230 | I21: =IF(ISBLANK(A21)=TRUE,0,1) -> 1 | J21: =IF(ISBLANK(B21)=TRUE,0,1) -> 1 | K21: =IF(ISBLANK(C21)=TRUE,0,1) -> 1 | L21: =IF(ISBLANK(D21)=TRUE,0,1) -> 1 | M21: =IF(ISBLANK(E21)=TRUE,0,1) -> 1 | N21: =IF(ISBLANK(F21)=TRUE,0,1) -> 1 | O21: =IF(ISBLANK(G21)=TRUE,0,1) -> 1 | P21: =IF(ISBLANK(H21)=TRUE,0,1) -> 0 | Q21: =IF(COUNTIF(A:A, A21) > 1, 0, 1) -> 1 | R21: =IF(ISERROR(VLOOKUP(A21, 'Project Reference'!A:A, 1, FALSE)), 0, 1) -> 1 | S21: =IFERROR(__xludf.DUMMYFUNCTION("IF(AND(REGEXMATCH(D21, B21), REGEXMATCH(D21, C21)), 1, 0)"),1.0) -> 1 | T21: =IF(AND(YEAR(E21)>=2023, YEAR(E21)<=2024), 1, 0) -> 1 | U21: =IF(F21-E21>=3, 1, 0) -> 1 | V21: =IF(G21>10000000000, 0, 1) -> 1
A22: CN-0137-2023 | B22: Jembatan | C22: Jakarta | D22: Perbaikan Jembatan Jakarta | E22: 45035 | F22: 45339 | G22: 4409857336 | I22: =IF(ISBLANK(A22)=TRUE,0,1) -> 1 | J22: =IF(ISBLANK(B22)=TRUE,0,1) -> 1 | K22: =IF(ISBLANK(C22)=TRUE,0,1) -> 1 | L22: =IF(ISBLANK(D22)=TRUE,0,1) -> 1 | M22: =IF(ISBLANK(E22)=TRUE,0,1) -> 1 | N22: =IF(ISBLANK(F22)=TRUE,0,1) -> 1 | O22: =IF(ISBLANK(G22)=TRUE,0,1) -> 1 | P22: =IF(ISBLANK(H22)=TRUE,0,1) -> 0 | Q22: =IF(COUNTIF(A:A, A22) > 1, 0, 1) -> 1 | R22: =IF(ISERROR(VLOOKUP(A22, 'Project Reference'!A:A, 1, FALSE)), 0, 1) -> 1 | S22: =IFERROR(__xludf.DUMMYFUNCTION("IF(AND(REGEXMATCH(D22, B22), REGEXMATCH(D22, C22)), 1, 0)"),1.0) -> 1 | T22: =IF(AND(YEAR(E22)>=2023, YEAR(E22)<=2024), 1, 0) -> 1 | U22: =IF(F22-E22>=3, 1, 0) -> 1 | V22: =IF(G22>10000000000, 0, 1) -> 1
A23: CN-0142-2023 | B23: Drainase | C23: Bandung | D23: Perbaikan Drainase Bandung | E23: 45036 | F23: 45313 | G23: 265879074 | I23: =IF(ISBLANK(A23)=TRUE,0,1) -> 1 | J23: =IF(ISBLANK(B23)=TRUE,0,1) -> 1 | K23: =IF(ISBLANK(C23)=TRUE,0,1) -> 1 | L23: =IF(ISBLANK(D23)=TRUE,0,1) -> 1 | M23: =IF(ISBLANK(E23)=TRUE,0,1) -> 1 | N23: =IF(ISBLANK(F23)=TRUE,0,1) -> 1 | O23: =IF(ISBLANK(G23)=TRUE,0,1) -> 1 | P23: =IF(ISBLANK(H23)=TRUE,0,1) -> 0 | Q23: =IF(COUNTIF(A:A, A23) > 1, 0, 1) -> 1 | R23: =IF(ISERROR(VLOOKUP(A23, 'Project Reference'!A:A, 1, FALSE)), 0, 1) -> 1 | S23: =IFERROR(__xludf.DUMMYFUNCTION("IF(AND(REGEXMATCH(D23, B23), REGEXMATCH(D23, C23)), 1, 0)"),1.0) -> 1 | T23: =IF(AND(YEAR(E23)>=2023, YEAR(E23)<=2024), 1, 0) -> 1 | U23: =IF(F23-E23>=3, 1, 0) -> 1 | V23: =IF(G23>10000000000, 0, 1) -> 1
A24: CN-0150-2023 | B24: Drainase | C24: Tomohon | D24: Perbaikan Drainase Tomohon | E24: 45042 | F24: 45364 | G24: 433880373 | I24: =IF(ISBLANK(A24)=TRUE,0,1) -> 1 | J24: =IF(ISBLANK(B24)=TRUE,0,1) -> 1 | K24: =IF(ISBLANK(C24)=TRUE,0,1) -> 1 | L24: =IF(ISBLANK(D24)=TRUE,0,1) -> 1 | M24: =IF(ISBLANK(E24)=TRUE,0,1) -> 1 | N24: =IF(ISBLANK(F24)=TRUE,0,1) -> 1 | O24: =IF(ISBLANK(G24)=TRUE,0,1) -> 1 | P24: =IF(ISBLANK(H24)=TRUE,0,1) -> 0 | Q24: =IF(COUNTIF(A:A, A24) > 1, 0, 1) -> 1 | R24: =IF(ISERROR(VLOOKUP(A24, 'Project Reference'!A:A, 1, FALSE)), 0, 1) -> 1 | S24: =IFERROR(__xludf.DUMMYFUNCTION("IF(AND(REGEXMATCH(D24, B24), REGEXMATCH(D24, C24)), 1, 0)"),1.0) -> 1 | T24: =IF(AND(YEAR(E24)>=2023, YEAR(E24)<=2024), 1, 0) -> 1 | U24: =IF(F24-E24>=3, 1, 0) -> 1 | V24: =IF(G24>10000000000, 0, 1) -> 1
A25: CN-0152-2023 | B25: Jalan Raya | C25: Surabaya | D25: Perbaikan Jalan Raya Surabaya | E25: 45045 | F25: 45324 | G25: 407950829 | I25: =IF(ISBLANK(A25)=TRUE,0,1) -> 1 | J25: =IF(ISBLANK(B25)=TRUE,0,1) -> 1 | K25: =IF(ISBLANK(C25)=TRUE,0,1) -> 1 | L25: =IF(ISBLANK(D25)=TRUE,0,1) -> 1 | M25: =IF(ISBLANK(E25)=TRUE,0,1) -> 1 | N25: =IF(ISBLANK(F25)=TRUE,0,1) -> 1 | O25: =IF(ISBLANK(G25)=TRUE,0,1) -> 1 | P25: =IF(ISBLANK(H25)=TRUE,0,1) -> 0 | Q25: =IF(COUNTIF(A:A, A25) > 1, 0, 1) -> 1 | R25: =IF(ISERROR(VLOOKUP(A25, 'Project Reference'!A:A, 1, FALSE)), 0, 1) -> 1 | S25: =IFERROR(__xludf.DUMMYFUNCTION("IF(AND(REGEXMATCH(D25, B25), REGEXMATCH(D25, C25)), 1, 0)"),1.0) -> 1 | T25: =IF(AND(YEAR(E25)>=2023, YEAR(E25)<=2024), 1, 0) -> 1 | U25: =IF(F25-E25>=3, 1, 0) -> 1 | V25: =IF(G25>10000000000, 0, 1) -> 1
A26: CN-0156-2023 | B26: Flyover | C26: Bau-Bau | D26: Pembuatan Flyover Bau-Bau | E26: 45048 | F26: 45358 | G26: 2665194797 | I26: =IF(ISBLANK(A26)=TRUE,0,1) -> 1 | J26: =IF(ISBLANK(B26)=TRUE,0,1) -> 1 | K26: =IF(ISBLANK(C26)=TRUE,0,1) -> 1 | L26: =IF(ISBLANK(D26)=TRUE,0,1) -> 1 | M26: =IF(ISBLANK(E26)=TRUE,0,1) -> 1 | N26: =IF(ISBLANK(F26)=TRUE,0,1) -> 1 | O26: =IF(ISBLANK(G26)=TRUE,0,1) -> 1 | P26: =IF(ISBLANK(H26)=TRUE,0,1) -> 0 | Q26: =IF(COUNTIF(A:A, A26) > 1, 0, 1) -> 1 | R26: =IF(ISERROR(VLOOKUP(A26, 'Project Reference'!A:A, 1, FALSE)), 0, 1) -> 1 | S26: =IFERROR(__xludf.DUMMYFUNCTION("IF(AND(REGEXMATCH(D26, B26), REGEXMATCH(D26, C26)), 1, 0)"),1.0) -> 1 | T26: =IF(AND(YEAR(E26)>=2023, YEAR(E26)<=2024), 1, 0) -> 1 | U26: =IF(F26-E26>=3, 1, 0) -> 1 | V26: =IF(G26>10000000000, 0, 1) -> 1
A27: CN-0157-2023 | B27: Jembatan | C27: Bau-Bau | D27: Perbaikan Jembatan Bau-Bau | E27: 45049 | F27: 45401 | G27: 2586947699 | I27: =IF(ISBLANK(A27)=TRUE,0,1) -> 1 | J27: =IF(ISBLANK(B27)=TRUE,0,1) -> 1 | K27: =IF(ISBLANK(C27)=TRUE,0,1) -> 1 | L27: =IF(ISBLANK(D27)=TRUE,0,1) -> 1 | M27: =IF(ISBLANK(E27)=TRUE,0,1) -> 1 | N27: =IF(ISBLANK(F27)=TRUE,0,1) -> 1 | O27: =IF(ISBLANK(G27)=TRUE,0,1) -> 1 | P27: =IF(ISBLANK(H27)=TRUE,0,1) -> 0 | Q27: =IF(COUNTIF(A:A, A27) > 1, 0, 1) -> 1 | R27: =IF(ISERROR(VLOOKUP(A27, 'Project Reference'!A:A, 1, FALSE)), 0, 1) -> 1 | S27: =IFERROR(__xludf.DUMMYFUNCTION("IF(AND(REGEXMATCH(D27, B27), REGEXMATCH(D27, C27)), 1, 0)"),1.0) -> 1 | T27: =IF(AND(YEAR(E27)>=2023, YEAR(E27)<=2024), 1, 0) -> 1 | U27: =IF(F27-E27>=3, 1, 0) -> 1 | V27: =IF(G27>10000000000, 0, 1) -> 1
A28: CN-0158-2023 | B28: Jalan Raya | C28: Bandung | D28: Perbaikan Jalan Raya Bandung | E28: 45052 | F28: 45087 | G28: 189032296 | I28: =IF(ISBLANK(A28)=TRUE,0,1) -> 1 | J28: =IF(ISBLANK(B28)=TRUE,0,1) -> 1 | K28: =IF(ISBLANK(C28)=TRUE,0,1) -> 1 | L28: =IF(ISBLANK(D28)=TRUE,0,1) -> 1 | M28: =IF(ISBLANK(E28)=TRUE,0,1) -> 1 | N28: =IF(ISBLANK(F28)=TRUE,0,1) -> 1 | O28: =IF(ISBLANK(G28)=TRUE,0,1) -> 1 | P28: =IF(ISBLANK(H28)=TRUE,0,1) -> 0 | Q28: =IF(COUNTIF(A:A, A28) > 1, 0, 1) -> 1 | R28: =IF(ISERROR(VLOOKUP(A28, 'Project Reference'!A:A, 1, FALSE)), 0, 1) -> 1 | S28: =IFERROR(__xludf.DUMMYFUNCTION("IF(AND(REGEXMATCH(D28, B28), REGEXMATCH(D28, C28)), 1, 0)"),1.0) -> 1 | T28: =IF(AND(YEAR(E28)>=2023, YEAR(E28)<=2024), 1, 0) -> 1 | U28: =IF(F28-E28>=3, 1, 0) -> 1 | V28: =IF(G28>10000000000, 0, 1) -> 1
A29: CN-0194-2023 | B29: Flyover | C29: Medan | D29: Pembuatan Flyover Medan | E29: 45078 | F29: 45220 | G29: 2544644297 | I29: =IF(ISBLANK(A29)=TRUE,0,1) -> 1 | J29: =IF(ISBLANK(B29)=TRUE,0,1) -> 1 | K29: =IF(ISBLANK(C29)=TRUE,0,1) -> 1 | L29: =IF(ISBLANK(D29)=TRUE,0,1) -> 1 | M29: =IF(ISBLANK(E29)=TRUE,0,1) -> 1 | N29: =IF(ISBLANK(F29)=TRUE,0,1) -> 1 | O29: =IF(ISBLANK(G29)=TRUE,0,1) -> 1 | P29: =IF(ISBLANK(H29)=TRUE,0,1) -> 0 | Q29: =IF(COUNTIF(A:A, A29) > 1, 0, 1) -> 1 | R29: =IF(ISERROR(VLOOKUP(A29, 'Project Reference'!A:A, 1, FALSE)), 0, 1) -> 1 | S29: =IFERROR(__xludf.DUMMYFUNCTION("IF(AND(REGEXMATCH(D29, B29), REGEXMATCH(D29, C29)), 1, 0)"),1.0) -> 1 | T29: =IF(AND(YEAR(E29)>=2023, YEAR(E29)<=2024), 1, 0) -> 1 | U29: =IF(F29-E29>=3, 1, 0) -> 1 | V29: =IF(G29>10000000000, 0, 1) -> 1
A30: CN-0211-2023 | B30: Gedung | C30: Jakarta | D30: Perbaikan Gedung Pemerintah Jakarta | E30: 45093 | F30: 45280 | G30: 6355661362 | I30: =IF(ISBLANK(A30)=TRUE,0,1) -> 1 | J30: =IF(ISBLANK(B30)=TRUE,0,1) -> 1 | K30: =IF(ISBLANK(C30)=TRUE,0,1) -> 1 | L30: =IF(ISBLANK(D30)=TRUE,0,1) -> 1 | M30: =IF(ISBLANK(E30)=TRUE,0,1) -> 1 | N30: =IF(ISBLANK(F30)=TRUE,0,1) -> 1 | O30: =IF(ISBLANK(G30)=TRUE,0,1) -> 1 | P30: =IF(ISBLANK(H30)=TRUE,0,1) -> 0 | Q30: =IF(COUNTIF(A:A, A30) > 1, 0, 1) -> 1 | R30: =IF(ISERROR(VLOOKUP(A30, 'Project Reference'!A:A, 1, FALSE)), 0, 1) -> 1 | S30: =IFERROR(__xludf.DUMMYFUNCTION("IF(AND(REGEXMATCH(D30, B30), REGEXMATCH(D30, C30)), 1, 0)"),1.0) -> 1 | T30: =IF(AND(YEAR(E30)>=2023, YEAR(E30)<=2024), 1, 0) -> 1 | U30: =IF(F30-E30>=3, 1, 0) -> 1 | V30: =IF(G30>10000000000, 0, 1) -> 1
A31: CN-0213-2023 | B31: Drainase | C31: Bandung | D31: Perbaikan Drainase Bandung | E31: 45095 | F31: 45423 | G31: 257229348 | I31: =IF(ISBLANK(A31)=TRUE,0,1) -> 1 | J31: =IF(ISBLANK(B31)=TRUE,0,1) -> 1 | K31: =IF(ISBLANK(C31)=TRUE,0,1) -> 1 | L31: =IF(ISBLANK(D31)=TRUE,0,1) -> 1 | M31: =IF(ISBLANK(E31)=TRUE,0,1) -> 1 | N31: =IF(ISBLANK(F31)=TRUE,0,1) -> 1 | O31: =IF(ISBLANK(G31)=TRUE,0,1) -> 1 | P31: =IF(ISBLANK(H31)=TRUE,0,1) -> 0 | Q31: =IF(COUNTIF(A:A, A31) > 1, 0, 1) -> 1 | R31: =IF(ISERROR(VLOOKUP(A31, 'Project Reference'!A:A, 1, FALSE)), 0, 1) -> 1 | S31: =IFERROR(__xludf.DUMMYFUNCTION("IF(AND(REGEXMATCH(D31, B31), REGEXMATCH(D31, C31)), 1, 0)"),1.0) -> 1 | T31: =IF(AND(YEAR(E31)>=2023, YEAR(E31)<=2024), 1, 0) -> 1 | U31: =IF(F31-E31>=3, 1, 0) -> 1 | V31: =IF(G31>10000000000, 0, 1) -> 1
A32: CN-0229-2023 | B32: Jembatan | C32: Tomohon | D32: Perbaikan Jembatan Tomohon | E32: 45106 | F32: 45212 | G32: 2498238869 | I32: =IF(ISBLANK(A32)=TRUE,0,1) -> 1 | J32: =IF(ISBLANK(B32)=TRUE,0,1) -> 1 | K32: =IF(ISBLANK(C32)=TRUE,0,1) -> 1 | L32: =IF(ISBLANK(D32)=TRUE,0,1) -> 1 | M32: =IF(ISBLANK(E32)=TRUE,0,1) -> 1 | N32: =IF(ISBLANK(F32)=TRUE,0,1) -> 1 | O32: =IF(ISBLANK(G32)=TRUE,0,1) -> 1 | P32: =IF(ISBLANK(H32)=TRUE,0,1) -> 0 | Q32: =IF(COUNTIF(A:A, A32) > 1, 0, 1) -> 1 | R32: =IF(ISERROR(VLOOKUP(A32, 'Project Reference'!A:A, 1, FALSE)), 0, 1) -> 1 | S32: =IFERROR(__xludf.DUMMYFUNCTION("IF(AND(REGEXMATCH(D32, B32), REGEXMATCH(D32, C32)), 1, 0)"),1.0) -> 1 | T32: =IF(AND(YEAR(E32)>=2023, YEAR(E32)<=2024), 1, 0) -> 1 | U32: =IF(F32-E32>=3, 1, 0) -> 1 | V32: =IF(G32>10000000000, 0, 1) -> 1
A33: CN-0244-2023 | B33: Flyover | C33: Jakarta | D33: Perbaikan Flyover Jakarta | E33: 45119 | F33: 45218 | G33: 4249269902 | I33: =IF(ISBLANK(A33)=TRUE,0,1) -> 1 | J33: =IF(ISBLANK(B33)=TRUE,0,1) -> 1 | K33: =IF(ISBLANK(C33)=TRUE,0,1) -> 1 | L33: =IF(ISBLANK(D33)=TRUE,0,1) -> 1 | M33: =IF(ISBLANK(E33)=TRUE,0,1) -> 1 | N33: =IF(ISBLANK(F33)=TRUE,0,1) -> 1 | O33: =IF(ISBLANK(G33)=TRUE,0,1) -> 1 | P33: =IF(ISBLANK(H33)=TRUE,0,1) -> 0 | Q33: =IF(COUNTIF(A:A, A33) > 1, 0, 1) -> 1 | R33: =IF(ISERROR(VLOOKUP(A33, 'Project Reference'!A:A, 1, FALSE)), 0, 1) -> 1 | S33: =IFERROR(__xludf.DUMMYFUNCTION("IF(AND(REGEXMATCH(D33, B33), REGEXMATCH(D33, C33)), 1, 0)"),1.0) -> 1 | T33: =IF(AND(YEAR(E33)>=2023, YEAR(E33)<=2024), 1, 0) -> 1 | U33: =IF(F33-E33>=3, 1, 0) -> 1 | V33: =IF(G33>10000000000, 0, 1) -> 1
A34: CN-0249-2023 | B34: Drainase | C34: Tomohon | D34: Perbaikan Drainase Tomohon | E34: 45124 | F34: 45421 | G34: 604130639 | I34: =IF(ISBLANK(A34)=TRUE,0,1) -> 1 | J34: =IF(ISBLANK(B34)=TRUE,0,1) -> 1 | K34: =IF(ISBLANK(C34)=TRUE,0,1) -> 1 | L34: =IF(ISBLANK(D34)=TRUE,0,1) -> 1 | M34: =IF(ISBLANK(E34)=TRUE,0,1) -> 1 | N34: =IF(ISBLANK(F34)=TRUE,0,1) -> 1 | O34: =IF(ISBLANK(G34)=TRUE,0,1) -> 1 | P34: =IF(ISBLANK(H34)=TRUE,0,1) -> 0 | Q34: =IF(COUNTIF(A:A, A34) > 1, 0, 1) -> 1 | R34: =IF(ISERROR(VLOOKUP(A34, 'Project Reference'!A:A, 1, FALSE)), 0, 1) -> 1 | S34: =IFERROR(__xludf.DUMMYFUNCTION("IF(AND(REGEXMATCH(D34, B34), REGEXMATCH(D34, C34)), 1, 0)"),1.0) -> 1 | T34: =IF(AND(YEAR(E34)>=2023, YEAR(E34)<=2024), 1, 0) -> 1 | U34: =IF(F34-E34>=3, 1, 0) -> 1 | V34: =IF(G34>10000000000, 0, 1) -> 1
A35: CN-0267-2023 | B35: Drainase | C35: Medan | D35: Perbaikan Drainase Medan | E35: 45130 | F35: 45277 | G35: 225164187 | I35: =IF(ISBLANK(A35)=TRUE,0,1) -> 1 | J35: =IF(ISBLANK(B35)=TRUE,0,1) -> 1 | K35: =IF(ISBLANK(C35)=TRUE,0,1) -> 1 | L35: =IF(ISBLANK(D35)=TRUE,0,1) -> 1 | M35: =IF(ISBLANK(E35)=TRUE,0,1) -> 1 | N35: =IF(ISBLANK(F35)=TRUE,0,1) -> 1 | O35: =IF(ISBLANK(G35)=TRUE,0,1) -> 1 | P35: =IF(ISBLANK(H35)=TRUE,0,1) -> 0 | Q35: =IF(COUNTIF(A:A, A35) > 1, 0, 1) -> 1 | R35: =IF(ISERROR(VLOOKUP(A35, 'Project Reference'!A:A, 1, FALSE)), 0, 1) -> 1 | S35: =IFERROR(__xludf.DUMMYFUNCTION("IF(AND(REGEXMATCH(D35, B35), REGEXMATCH(D35, C35)), 1, 0)"),1.0) -> 1 | T35: =IF(AND(YEAR(E35)>=2023, YEAR(E35)<=2024), 1, 0) -> 1 | U35: =IF(F35-E35>=3, 1, 0) -> 1 | V35: =IF(G35>10000000000, 0, 1) -> 1
A36: CN-0282-2023 | B36: Flyover | C36: Makassar | D36: Pembuatan Flyover Makassar | E36: 45138 | F36: 45260 | G36: 3767875960 | I36: =IF(ISBLANK(A36)=TRUE,0,1) -> 1 | J36: =IF(ISBLANK(B36)=TRUE,0,1) -> 1 | K36: =IF(ISBLANK(C36)=TRUE,0,1) -> 1 | L36: =IF(ISBLANK(D36)=TRUE,0,1) -> 1 | M36: =IF(ISBLANK(E36)=TRUE,0,1) -> 1 | N36: =IF(ISBLANK(F36)=TRUE,0,1) -> 1 | O36: =IF(ISBLANK(G36)=TRUE,0,1) -> 1 | P36: =IF(ISBLANK(H36)=TRUE,0,1) -> 0 | Q36: =IF(COUNTIF(A:A, A36) > 1, 0, 1) -> 1 | R36: =IF(ISERROR(VLOOKUP(A36, 'Project Reference'!A:A, 1, FALSE)), 0, 1) -> 1 | S36: =IFERROR(__xludf.DUMMYFUNCTION("IF(AND(REGEXMATCH(D36, B36), REGEXMATCH(D36, C36)), 1, 0)"),1.0) -> 1 | T36: =IF(AND(YEAR(E36)>=2023, YEAR(E36)<=2024), 1, 0) -> 1 | U36: =IF(F36-E36>=3, 1, 0) -> 1 | V36: =IF(G36>10000000000, 0, 1) -> 1
A37: CN-0289-2023 | B37: Flyover | C37: Jakarta | D37: Pembuatan Flyover Jakarta | E37: 45144 | F37: 45187 | G37: 4486128429 | I37: =IF(ISBLANK(A37)=TRUE,0,1) -> 1 | J37: =IF(ISBLANK(B37)=TRUE,0,1) -> 1 | K37: =IF(ISBLANK(C37)=TRUE,0,1) -> 1 | L37: =IF(ISBLANK(D37)=TRUE,0,1) -> 1 | M37: =IF(ISBLANK(E37)=TRUE,0,1) -> 1 | N37: =IF(ISBLANK(F37)=TRUE,0,1) -> 1 | O37: =IF(ISBLANK(G37)=TRUE,0,1) -> 1 | P37: =IF(ISBLANK(H37)=TRUE,0,1) -> 0 | Q37: =IF(COUNTIF(A:A, A37) > 1, 0, 1) -> 1 | R37: =IF(ISERROR(VLOOKUP(A37, 'Project Reference'!A:A, 1, FALSE)), 0, 1) -> 1 | S37: =IFERROR(__xludf.DUMMYFUNCTION("IF(AND(REGEXMATCH(D37, B37), REGEXMATCH(D37, C37)), 1, 0)"),1.0) -> 1 | T37: =IF(AND(YEAR(E37)>=2023, YEAR(E37)<=2024), 1, 0) -> 1 | U37: =IF(F37-E37>=3, 1, 0) -> 1 | V37: =IF(G37>10000000000, 0, 1) -> 1
A38: CN-0297-2023 | B38: Drainase | C38: Tomohon | D38: Perbaikan Drainase Tomohon | E38: 45154 | F38: 45341 | G38: 442886883 | I38: =IF(ISBLANK(A38)=TRUE,0,1) -> 1 | J38: =IF(ISBLANK(B38)=TRUE,0,1) -> 1 | K38: =IF(ISBLANK(C38)=TRUE,0,1) -> 1 | L38: =IF(ISBLANK(D38)=TRUE,0,1) -> 1 | M38: =IF(ISBLANK(E38)=TRUE,0,1) -> 1 | N38: =IF(ISBLANK(F38)=TRUE,0,1) -> 1 | O38: =IF(ISBLANK(G38)=TRUE,0,1) -> 1 | P38: =IF(ISBLANK(H38)=TRUE,0,1) -> 0 | Q38: =IF(COUNTIF(A:A, A38) > 1, 0, 1) -> 1 | R38: =IF(ISERROR(VLOOKUP(A38, 'Project Reference'!A:A, 1, FALSE)), 0, 1) -> 1 | S38: =IFERROR(__xludf.DUMMYFUNCTION("IF(AND(REGEXMATCH(D38, B38), REGEXMATCH(D38, C38)), 1, 0)"),1.0) -> 1 | T38: =IF(AND(YEAR(E38)>=2023, YEAR(E38)<=2024), 1, 0) -> 1 | U38: =IF(F38-E38>=3, 1, 0) -> 1 | V38: =IF(G38>10000000000, 0, 1) -> 1
A39: CN-0300-2023 | B39: Jalan Raya | C39: Medan | D39: Perbaikan Jalan Raya Medan | E39: 45157 | F39: 45305 | G39: 616245876 | I39: =IF(ISBLANK(A39)=TRUE,0,1) -> 1 | J39: =IF(ISBLANK(B39)=TRUE,0,1) -> 1 | K39: =IF(ISBLANK(C39)=TRUE,0,1) -> 1 | L39: =IF(ISBLANK(D39)=TRUE,0,1) -> 1 | M39: =IF(ISBLANK(E39)=TRUE,0,1) -> 1 | N39: =IF(ISBLANK(F39)=TRUE,0,1) -> 1 | O39: =IF(ISBLANK(G39)=TRUE,0,1) -> 1 | P39: =IF(ISBLANK(H39)=TRUE,0,1) -> 0 | Q39: =IF(COUNTIF(A:A, A39) > 1, 0, 1) -> 1 | R39: =IF(ISERROR(VLOOKUP(A39, 'Project Reference'!A:A, 1, FALSE)), 0, 1) -> 1 | S39: =IFERROR(__xludf.DUMMYFUNCTION("IF(AND(REGEXMATCH(D39, B39), REGEXMATCH(D39, C39)), 1, 0)"),1.0) -> 1 | T39: =IF(AND(YEAR(E39)>=2023, YEAR(E39)<=2024), 1, 0) -> 1 | U39: =IF(F39-E39>=3, 1, 0) -> 1 | V39: =IF(G39>10000000000, 0, 1) -> 1
A40: CN-0304-2023 | B40: Flyover | C40: Depok | D40: Perbaikan Flyover Depok | E40: 45160 | F40: 45415 | G40: 2178901994 | I40: =IF(ISBLANK(A40)=TRUE,0,1) -> 1 | J40: =IF(ISBLANK(B40)=TRUE,0,1) -> 1 | K40: =IF(ISBLANK(C40)=TRUE,0,1) -> 1 | L40: =IF(ISBLANK(D40)=TRUE,0,1) -> 1 | M40: =IF(ISBLANK(E40)=TRUE,0,1) -> 1 | N40: =IF(ISBLANK(F40)=TRUE,0,1) -> 1 | O40: =IF(ISBLANK(G40)=TRUE,0,1) -> 1 | P40: =IF(ISBLANK(H40)=TRUE,0,1) -> 0 | Q40: =IF(COUNTIF(A:A, A40) > 1, 0, 1) -> 1 | R40: =IF(ISERROR(VLOOKUP(A40, 'Project Reference'!A:A, 1, FALSE)), 0, 1) -> 1 | S40: =IFERROR(__xludf.DUMMYFUNCTION("IF(AND(REGEXMATCH(D40, B40), REGEXMATCH(D40, C40)), 1, 0)"),1.0) -> 1 | T40: =IF(AND(YEAR(E40)>=2023, YEAR(E40)<=2024), 1, 0) -> 1 | U40: =IF(F40-E40>=3, 1, 0) -> 1 | V40: =IF(G40>10000000000, 0, 1) -> 1
...

Sheet Data Cleaning
A1: ID_Proyek | B1: Jenis_Proyek | C1: Lokasi | D1: Nama_Proyek | E1: Tanggal_Mulai | F1: Tanggal_Selesai | G1: Anggaran | H1: Kontraktor | I1: CPT_ID_Proyek | J1: CPT_Jenis_Proyek | K1: CPT_Lokasi | L1: CPT_Nama_Proyek | M1: CPT_Tanggal_Mulai | N1: CPT_Tanggal_Selesai | O1: CPT_Anggaran | P1: CPT_Kontraktor | Q1: UNQ_ID_Proyek | R1: VLD_ID_Proyek | S1: CNS_Nama_Proyek | T1: FSB_Tanggal_Mulai | U1: FSB_Tanggal_Selesai | V1: FSB_Anggaran
A2: CN-0011-2024 | B2: Flyover | C2: Bandung | D2: Pembuatan Flyover Bandung | E2: 45336 | F2: 45336 | G2: 3981092285 | H2: PT D | I2: =IF(ISBLANK(A2)=TRUE,0,1) -> 1 | J2: =IF(ISBLANK(B2)=TRUE,0,1) -> 1 | K2: =IF(ISBLANK(C2)=TRUE,0,1) -> 1 | L2: =IF(ISBLANK(D2)=TRUE,0,1) -> 1 | M2: =IF(ISBLANK(E2)=TRUE,0,1) -> 1 | N2: =IF(ISBLANK(F2)=TRUE,0,1) -> 1 | O2: =IF(ISBLANK(G2)=TRUE,0,1) -> 1 | P2: =IF(ISBLANK(H2)=TRUE,0,1) -> 1 | Q2: =IF(COUNTIF(A:A, A2) > 1, 0, 1) -> 1 | R2: =IF(ISERROR(VLOOKUP(A2, 'Project Reference'!A:A, 1, FALSE)), 0, 1) -> 1 | S2: =IFERROR(__xludf.DUMMYFUNCTION("IF(AND(REGEXMATCH(D2, B2), REGEXMATCH(D2, C2)), 1, 0) "),1.0) -> 1 | T2: =IF(AND(YEAR(E2)>=2023, YEAR(E2)<=2024), 1, 0) -> 1 | U2: =IF(F2-E2>=3, 1, 0) -> 0 | V2: =IF(G2>10000000000, 0, 1) -> 1
A3: CN-0162-2023 | B3: Jalan Raya | C3: Bau-Bau | D3: Perbaikan Jalan Raya Bau-Bau | E3: 45055 | F3: 44950 | G3: 862295964 | H3: PT B | I3: =IF(ISBLANK(A3)=TRUE,0,1) -> 1 | J3: =IF(ISBLANK(B3)=TRUE,0,1) -> 1 | K3: =IF(ISBLANK(C3)=TRUE,0,1) -> 1 | L3: =IF(ISBLANK(D3)=TRUE,0,1) -> 1 | M3: =IF(ISBLANK(E3)=TRUE,0,1) -> 1 | N3: =IF(ISBLANK(F3)=TRUE,0,1) -> 1 | O3: =IF(ISBLANK(G3)=TRUE,0,1) -> 1 | P3: =IF(ISBLANK(H3)=TRUE,0,1) -> 1 | Q3: =IF(COUNTIF(A:A, A3) > 1, 0, 1) -> 1 | R3: =IF(ISERROR(VLOOKUP(A3, 'Project Reference'!A:A, 1, FALSE)), 0, 1) -> 1 | S3: =IFERROR(__xludf.DUMMYFUNCTION("IF(AND(REGEXMATCH(D3, B3), REGEXMATCH(D3, C3)), 1, 0) "),1.0) -> 1 | T3: =IF(AND(YEAR(E3)>=2023, YEAR(E3)<=2024), 1, 0) -> 1 | U3: =IF(F3-E3>=3, 1, 0) -> 0 | V3: =IF(G3>10000000000, 0, 1) -> 1
A4: CN-0208-2023 | B4: Drainase | C4: Bandung | D4: Perbaikan Drainase Bandung | E4: 45091 | F4: 45091 | G4: 612637613 | H4: PT B | I4: =IF(ISBLANK(A4)=TRUE,0,1) -> 1 | J4: =IF(ISBLANK(B4)=TRUE,0,1) -> 1 | K4: =IF(ISBLANK(C4)=TRUE,0,1) -> 1 | L4: =IF(ISBLANK(D4)=TRUE,0,1) -> 1 | M4: =IF(ISBLANK(E4)=TRUE,0,1) -> 1 | N4: =IF(ISBLANK(F4)=TRUE,0,1) -> 1 | O4: =IF(ISBLANK(G4)=TRUE,0,1) -> 1 | P4: =IF(ISBLANK(H4)=TRUE,0,1) -> 1 | Q4: =IF(COUNTIF(A:A, A4) > 1, 0, 1) -> 1 | R4: =IF(ISERROR(VLOOKUP(A4, 'Project Reference'!A:A, 1, FALSE)), 0, 1) -> 1 | S4: =IFERROR(__xludf.DUMMYFUNCTION("IF(AND(REGEXMATCH(D4, B4), REGEXMATCH(D4, C4)), 1, 0) "),1.0) -> 1 | T4: =IF(AND(YEAR(E4)>=2023, YEAR(E4)<=2024), 1, 0) -> 1 | U4: =IF(F4-E4>=3, 1, 0) -> 0 | V4: =IF(G4>10000000000, 0, 1) -> 1
A5: CN-0226-2023 | B5: Jalan Raya | C5: Tomohon | D5: Perbaikan Jalan Raya Tomohon | E5: 45103 | F5: 45038 | G5: 277801695 | H5: PT. Lailasari Hariyah (Persero) Tbk | I5: =IF(ISBLANK(A5)=TRUE,0,1) -> 1 | J5: =IF(ISBLANK(B5)=TRUE,0,1) -> 1 | K5: =IF(ISBLANK(C5)=TRUE,0,1) -> 1 | L5: =IF(ISBLANK(D5)=TRUE,0,1) -> 1 | M5: =IF(ISBLANK(E5)=TRUE,0,1) -> 1 | N5: =IF(ISBLANK(F5)=TRUE,0,1) -> 1 | O5: =IF(ISBLANK(G5)=TRUE,0,1) -> 1 | P5: =IF(ISBLANK(H5)=TRUE,0,1) -> 1 | Q5: =IF(COUNTIF(A:A, A5) > 1, 0, 1) -> 1 | R5: =IF(ISERROR(VLOOKUP(A5, 'Project Reference'!A:A, 1, FALSE)), 0, 1) -> 1 | S5: =IFERROR(__xludf.DUMMYFUNCTION("IF(AND(REGEXMATCH(D5, B5), REGEXMATCH(D5, C5)), 1, 0) "),1.0) -> 1 | T5: =IF(AND(YEAR(E5)>=2023, YEAR(E5)<=2024), 1, 0) -> 1 | U5: =IF(F5-E5>=3, 1, 0) -> 0 | V5: =IF(G5>10000000000, 0, 1) -> 1
A6: CN-0264-2023 | B6: Jembatan | C6: Medan | D6: Perbaikan Jembatan Medan | E6: 45129 | F6: 44945 | G6: 2045004222 | H6: PT B | I6: =IF(ISBLANK(A6)=TRUE,0,1) -> 1 | J6: =IF(ISBLANK(B6)=TRUE,0,1) -> 1 | K6: =IF(ISBLANK(C6)=TRUE,0,1) -> 1 | L6: =IF(ISBLANK(D6)=TRUE,0,1) -> 1 | M6: =IF(ISBLANK(E6)=TRUE,0,1) -> 1 | N6: =IF(ISBLANK(F6)=TRUE,0,1) -> 1 | O6: =IF(ISBLANK(G6)=TRUE,0,1) -> 1 | P6: =IF(ISBLANK(H6)=TRUE,0,1) -> 1 | Q6: =IF(COUNTIF(A:A, A6) > 1, 0, 1) -> 1 | R6: =IF(ISERROR(VLOOKUP(A6, 'Project Reference'!A:A, 1, FALSE)), 0, 1) -> 1 | S6: =IFERROR(__xludf.DUMMYFUNCTION("IF(AND(REGEXMATCH(D6, B6), REGEXMATCH(D6, C6)), 1, 0) "),1.0) -> 1 | T6: =IF(AND(YEAR(E6)>=2023, YEAR(E6)<=2024), 1, 0) -> 1 | U6: =IF(F6-E6>=3, 1, 0) -> 0 | V6: =IF(G6>10000000000, 0, 1) -> 1
A7: CN-0283-2023 | B7: Gedung | C7: Bandung | D7: Perbaikan Gedung Pemerintah Bandung | E7: 45140 | F7: 45090 | G7: 8403683934 | H7: PT D | I7: =IF(ISBLANK(A7)=TRUE,0,1) -> 1 | J7: =IF(ISBLANK(B7)=TRUE,0,1) -> 1 | K7: =IF(ISBLANK(C7)=TRUE,0,1) -> 1 | L7: =IF(ISBLANK(D7)=TRUE,0,1) -> 1 | M7: =IF(ISBLANK(E7)=TRUE,0,1) -> 1 | N7: =IF(ISBLANK(F7)=TRUE,0,1) -> 1 | O7: =IF(ISBLANK(G7)=TRUE,0,1) -> 1 | P7: =IF(ISBLANK(H7)=TRUE,0,1) -> 1 | Q7: =IF(COUNTIF(A:A, A7) > 1, 0, 1) -> 1 | R7: =IF(ISERROR(VLOOKUP(A7, 'Project Reference'!A:A, 1, FALSE)), 0, 1) -> 1 | S7: =IFERROR(__xludf.DUMMYFUNCTION("IF(AND(REGEXMATCH(D7, B7), REGEXMATCH(D7, C7)), 1, 0) "),1.0) -> 1 | T7: =IF(AND(YEAR(E7)>=2023, YEAR(E7)<=2024), 1, 0) -> 1 | U7: =IF(F7-E7>=3, 1, 0) -> 0 | V7: =IF(G7>10000000000, 0, 1) -> 1
A8: CN-0308-2023 | B8: Jembatan | C8: Depok | D8: Perbaikan Jembatan Depok | E8: 45161 | F8: 45100 | G8: 775460621 | H8: PT. Lailasari Hariyah (Persero) Tbk | I8: =IF(ISBLANK(A8)=TRUE,0,1) -> 1 | J8: =IF(ISBLANK(B8)=TRUE,0,1) -> 1 | K8: =IF(ISBLANK(C8)=TRUE,0,1) -> 1 | L8: =IF(ISBLANK(D8)=TRUE,0,1) -> 1 | M8: =IF(ISBLANK(E8)=TRUE,0,1) -> 1 | N8: =IF(ISBLANK(F8)=TRUE,0,1) -> 1 | O8: =IF(ISBLANK(G8)=TRUE,0,1) -> 1 | P8: =IF(ISBLANK(H8)=TRUE,0,1) -> 1 | Q8: =IF(COUNTIF(A:A, A8) > 1, 0, 1) -> 1 | R8: =IF(ISERROR(VLOOKUP(A8, 'Project Reference'!A:A, 1, FALSE)), 0, 1) -> 1 | S8: =IFERROR(__xludf.DUMMYFUNCTION("IF(AND(REGEXMATCH(D8, B8), REGEXMATCH(D8, C8)), 1, 0) "),1.0) -> 1 | T8: =IF(AND(YEAR(E8)>=2023, YEAR(E8)<=2024), 1, 0) -> 1 | U8: =IF(F8-E8>=3, 1, 0) -> 0 | V8: =IF(G8>10000000000, 0, 1) -> 1
A9: CN-0370-2023 | B9: Jalan Raya | C9: Bandung | D9: Perbaikan Jalan Raya Bandung | E9: 45207 | F9: 45141 | G9: 371601786 | H9: PT. Lailasari Hariyah (Persero) Tbk | I9: =IF(ISBLANK(A9)=TRUE,0,1) -> 1 | J9: =IF(ISBLANK(B9)=TRUE,0,1) -> 1 | K9: =IF(ISBLANK(C9)=TRUE,0,1) -> 1 | L9: =IF(ISBLANK(D9)=TRUE,0,1) -> 1 | M9: =IF(ISBLANK(E9)=TRUE,0,1) -> 1 | N9: =IF(ISBLANK(F9)=TRUE,0,1) -> 1 | O9: =IF(ISBLANK(G9)=TRUE,0,1) -> 1 | P9: =IF(ISBLANK(H9)=TRUE,0,1) -> 1 | Q9: =IF(COUNTIF(A:A, A9) > 1, 0, 1) -> 1 | R9: =IF(ISERROR(VLOOKUP(A9, 'Project Reference'!A:A, 1, FALSE)), 0, 1) -> 1 | S9: =IFERROR(__xludf.DUMMYFUNCTION("IF(AND(REGEXMATCH(D9, B9), REGEXMATCH(D9, C9)), 1, 0) "),1.0) -> 1 | T9: =IF(AND(YEAR(E9)>=2023, YEAR(E9)<=2024), 1, 0) -> 1 | U9: =IF(F9-E9>=3, 1, 0) -> 0 | V9: =IF(G9>10000000000, 0, 1) -> 1
A10: CN-0406-2023 | B10: Jembatan | C10: Bandung | D10: Pembuatan Jembatan Bandung | E10: 45240 | F10: 44995 | G10: 2771182474 | H10: PT D | I10: =IF(ISBLANK(A10)=TRUE,0,1) -> 1 | J10: =IF(ISBLANK(B10)=TRUE,0,1) -> 1 | K10: =IF(ISBLANK(C10)=TRUE,0,1) -> 1 | L10: =IF(ISBLANK(D10)=TRUE,0,1) -> 1 | M10: =IF(ISBLANK(E10)=TRUE,0,1) -> 1 | N10: =IF(ISBLANK(F10)=TRUE,0,1) -> 1 | O10: =IF(ISBLANK(G10)=TRUE,0,1) -> 1 | P10: =IF(ISBLANK(H10)=TRUE,0,1) -> 1 | Q10: =IF(COUNTIF(A:A, A10) > 1, 0, 1) -> 1 | R10: =IF(ISERROR(VLOOKUP(A10, 'Project Reference'!A:A, 1, FALSE)), 0, 1) -> 1 | S10: =IFERROR(__xludf.DUMMYFUNCTION("IF(AND(REGEXMATCH(D10, B10), REGEXMATCH(D10, C10)), 1, 0) "),1.0) -> 1 | T10: =IF(AND(YEAR(E10)>=2023, YEAR(E10)<=2024), 1, 0) -> 1 | U10: =IF(F10-E10>=3, 1, 0) -> 0 | V10: =IF(G10>10000000000, 0, 1) -> 1
A11: CN-0409-2023 | B11: Flyover | C11: Jakarta | D11: Pembuatan Flyover Jakarta | E11: 45240 | F11: 45074 | G11: 4659030076 | I11: =IF(ISBLANK(A11)=TRUE,0,1) -> 1 | J11: =IF(ISBLANK(B11)=TRUE,0,1) -> 1 | K11: =IF(ISBLANK(C11)=TRUE,0,1) -> 1 | L11: =IF(ISBLANK(D11)=TRUE,0,1) -> 1 | M11: =IF(ISBLANK(E11)=TRUE,0,1) -> 1 | N11: =IF(ISBLANK(F11)=TRUE,0,1) -> 1 | O11: =IF(ISBLANK(G11)=TRUE,0,1) -> 1 | P11: =IF(ISBLANK(H11)=TRUE,0,1) -> 0 | Q11: =IF(COUNTIF(A:A, A11) > 1, 0, 1) -> 1 | R11: =IF(ISERROR(VLOOKUP(A11, 'Project Reference'!A:A, 1, FALSE)), 0, 1) -> 1 | S11: =IFERROR(__xludf.DUMMYFUNCTION("IF(AND(REGEXMATCH(D11, B11), REGEXMATCH(D11, C11)), 1, 0) "),1.0) -> 1 | T11: =IF(AND(YEAR(E11)>=2023, YEAR(E11)<=2024), 1, 0) -> 1 | U11: =IF(F11-E11>=3, 1, 0) -> 0 | V11: =IF(G11>10000000000, 0, 1) -> 1
A12: CN-0413-2023 | B12: Drainase | C12: Surabaya | D12: Perbaikan Drainase Surabaya | E12: 45241 | F12: 44946 | G12: 308009410 | H12: PT A | I12: =IF(ISBLANK(A12)=TRUE,0,1) -> 1 | J12: =IF(ISBLANK(B12)=TRUE,0,1) -> 1 | K12: =IF(ISBLANK(C12)=TRUE,0,1) -> 1 | L12: =IF(ISBLANK(D12)=TRUE,0,1) -> 1 | M12: =IF(ISBLANK(E12)=TRUE,0,1) -> 1 | N12: =IF(ISBLANK(F12)=TRUE,0,1) -> 1 | O12: =IF(ISBLANK(G12)=TRUE,0,1) -> 1 | P12: =IF(ISBLANK(H12)=TRUE,0,1) -> 1 | Q12: =IF(COUNTIF(A:A, A12) > 1, 0, 1) -> 1 | R12: =IF(ISERROR(VLOOKUP(A12, 'Project Reference'!A:A, 1, FALSE)), 0, 1) -> 1 | S12: =IFERROR(__xludf.DUMMYFUNCTION("IF(AND(REGEXMATCH(D12, B12), REGEXMATCH(D12, C12)), 1, 0) "),1.0) -> 1 | T12: =IF(AND(YEAR(E12)>=2023, YEAR(E12)<=2024), 1, 0) -> 1 | U12: =IF(F12-E12>=3, 1, 0) -> 0 | V12: =IF(G12>10000000000, 0, 1) -> 1
A13: CN-0415-2023 | B13: Jembatan | C13: Medan | D13: Pembuatan Jembatan Medan | E13: 45242 | F13: 45098 | G13: 5932217911 | H13: CV Sihombing | I13: =IF(ISBLANK(A13)=TRUE,0,1) -> 1 | J13: =IF(ISBLANK(B13)=TRUE,0,1) -> 1 | K13: =IF(ISBLANK(C13)=TRUE,0,1) -> 1 | L13: =IF(ISBLANK(D13)=TRUE,0,1) -> 1 | M13: =IF(ISBLANK(E13)=TRUE,0,1) -> 1 | N13: =IF(ISBLANK(F13)=TRUE,0,1) -> 1 | O13: =IF(ISBLANK(G13)=TRUE,0,1) -> 1 | P13: =IF(ISBLANK(H13)=TRUE,0,1) -> 1 | Q13: =IF(COUNTIF(A:A, A13) > 1, 0, 1) -> 1 | R13: =IF(ISERROR(VLOOKUP(A13, 'Project Reference'!A:A, 1, FALSE)), 0, 1) -> 1 | S13: =IFERROR(__xludf.DUMMYFUNCTION("IF(AND(REGEXMATCH(D13, B13), REGEXMATCH(D13, C13)), 1, 0) "),1.0) -> 1 | T13: =IF(AND(YEAR(E13)>=2023, YEAR(E13)<=2024), 1, 0) -> 1 | U13: =IF(F13-E13>=3, 1, 0) -> 0 | V13: =IF(G13>10000000000, 0, 1) -> 1
A14: CN-0473-2023 | B14: Gedung | C14: Bau-Bau | D14: Perbaikan Gedung Pemerintah Bau-Bau | E14: 45286 | F14: 45044 | G14: 9221677626 | H14: PT. Yuniar Hakim Tbk | I14: =IF(ISBLANK(A14)=TRUE,0,1) -> 1 | J14: =IF(ISBLANK(B14)=TRUE,0,1) -> 1 | K14: =IF(ISBLANK(C14)=TRUE,0,1) -> 1 | L14: =IF(ISBLANK(D14)=TRUE,0,1) -> 1 | M14: =IF(ISBLANK(E14)=TRUE,0,1) -> 1 | N14: =IF(ISBLANK(F14)=TRUE,0,1) -> 1 | O14: =IF(ISBLANK(G14)=TRUE,0,1) -> 1 | P14: =IF(ISBLANK(H14)=TRUE,0,1) -> 1 | Q14: =IF(COUNTIF(A:A, A14) > 1, 0, 1) -> 1 | R14: =IF(ISERROR(VLOOKUP(A14, 'Project Reference'!A:A, 1, FALSE)), 0, 1) -> 1 | S14: =IFERROR(__xludf.DUMMYFUNCTION("IF(AND(REGEXMATCH(D14, B14), REGEXMATCH(D14, C14)), 1, 0) "),1.0) -> 1 | T14: =IF(AND(YEAR(E14)>=2023, YEAR(E14)<=2024), 1, 0) -> 1 | U14: =IF(F14-E14>=3, 1, 0) -> 0 | V14: =IF(G14>10000000000, 0, 1) -> 1
A15: CN-9999-2024 | B15: Jalan Raya | C15: Jakarta | D15: Tes | E15: 45292 | F15: 45292 | G15: 105133426 | H15: x | I15: =IF(ISBLANK(A15)=TRUE,0,1) -> 1 | J15: =IF(ISBLANK(B15)=TRUE,0,1) -> 1 | K15: =IF(ISBLANK(C15)=TRUE,0,1) -> 1 | L15: =IF(ISBLANK(D15)=TRUE,0,1) -> 1 | M15: =IF(ISBLANK(E15)=TRUE,0,1) -> 1 | N15: =IF(ISBLANK(F15)=TRUE,0,1) -> 1 | O15: =IF(ISBLANK(G15)=TRUE,0,1) -> 1 | P15: =IF(ISBLANK(H15)=TRUE,0,1) -> 1 | Q15: =IF(COUNTIF(A:A, A15) > 1, 0, 1) -> 1 | R15: =IF(ISERROR(VLOOKUP(A15, 'Project Reference'!A:A, 1, FALSE)), 0, 1) -> 0 | S15: =IFERROR(__xludf.DUMMYFUNCTION("IF(AND(REGEXMATCH(D15, B15), REGEXMATCH(D15, C15)), 1, 0) "),0.0) -> 0 | T15: =IF(AND(YEAR(E15)>=2023, YEAR(E15)<=2024), 1, 0) -> 1 | U15: =IF(F15-E15>=3, 1, 0) -> 0 | V15: =IF(G15>10000000000, 0, 1) -> 1
A16: CN-0001-2023 | B16: Drainase | C16: Bandung | D16: Perbaikan Drainase Bandung | E16: 44927 | F16: 44994 | G16: 649208256 | H16: PT. Lailasari Hariyah (Persero) Tbk | I16: =IF(ISBLANK(A16)=TRUE,0,1) -> 1 | J16: =IF(ISBLANK(B16)=TRUE,0,1) -> 1 | K16: =IF(ISBLANK(C16)=TRUE,0,1) -> 1 | L16: =IF(ISBLANK(D16)=TRUE,0,1) -> 1 | M16: =IF(ISBLANK(E16)=TRUE,0,1) -> 1 | N16: =IF(ISBLANK(F16)=TRUE,0,1) -> 1 | O16: =IF(ISBLANK(G16)=TRUE,0,1) -> 1 | P16: =IF(ISBLANK(H16)=TRUE,0,1) -> 1 | Q16: =IF(COUNTIF(A:A, A16) > 1, 0, 1) -> 1 | R16: =IF(ISERROR(VLOOKUP(A16, 'Project Reference'!A:A, 1, FALSE)), 0, 1) -> 1 | S16: =IFERROR(__xludf.DUMMYFUNCTION("IF(AND(REGEXMATCH(D16, B16), REGEXMATCH(D16, C16)), 1, 0) "),1.0) -> 1 | T16: =IF(AND(YEAR(E16)>=2023, YEAR(E16)<=2024), 1, 0) -> 1 | U16: =IF(F16-E16>=3, 1, 0) -> 1 | V16: =IF(G16>10000000000, 0, 1) -> 1
A17: CN-0001-2024 | B17: Drainase | C17: Surabaya | D17: Perbaikan Drainase Surabaya | E17: 45319 | F17: 45323 | G17: 326999652 | H17: CV Sihombing | I17: =IF(ISBLANK(A17)=TRUE,0,1) -> 1 | J17: =IF(ISBLANK(B17)=TRUE,0,1) -> 1 | K17: =IF(ISBLANK(C17)=TRUE,0,1) -> 1 | L17: =IF(ISBLANK(D17)=TRUE,0,1) -> 1 | M17: =IF(ISBLANK(E17)=TRUE,0,1) -> 1 | N17: =IF(ISBLANK(F17)=TRUE,0,1) -> 1 | O17: =IF(ISBLANK(G17)=TRUE,0,1) -> 1 | P17: =IF(ISBLANK(H17)=TRUE,0,1) -> 1 | Q17: =IF(COUNTIF(A:A, A17) > 1, 0, 1) -> 1 | R17: =IF(ISERROR(VLOOKUP(A17, 'Project Reference'!A:A, 1, FALSE)), 0, 1) -> 1 | S17: =IFERROR(__xludf.DUMMYFUNCTION("IF(AND(REGEXMATCH(D17, B17), REGEXMATCH(D17, C17)), 1, 0) "),1.0) -> 1 | T17: =IF(AND(YEAR(E17)>=2023, YEAR(E17)<=2024), 1, 0) -> 1 | U17: =IF(F17-E17>=3, 1, 0) -> 1 | V17: =IF(G17>10000000000, 0, 1) -> 1
